Workbook

Sheet Summary
A1: BU 2027 | B1: Описание: сводный P&L AdTech 2027 по месяцам и за год vs FC 2026, млн ₽. Логика: ссылки на «P&L 2027» | S1: Bridge to strategy | U1: Описание: сверка BU 2027 со стратегией. | X1: CONS BU 2027 | Y1: Описание: вид для консолидации. Логика: E-comm / Offline = прирост выручки 2027 к FC 2026 (кол. DIFF); расходы - BU 2027 | AB1: CONS STR 2027 | AE1: Описание: сверка BU 2027 с консолидационной формой в стратегии
A2: Статья | B2: янв | C2: фев | D2: мар | E2: апр | F2: май | G2: июн | H2: июл | I2: авг | J2: сен | K2: окт | L2: ноя | M2: дек | N2: 2027 BU | O2: 2026 FC | P2: DIFF | Q2: YoY | S2: Strategy 2027 | T2: DIFF | U2: % | X2: Статья | Y2: 2027 BU | AB2: Статья | AC2: 2027 STR | AD2: DIFF | AE2: %
A3: APP | B3: ='P&L 2027'!B5 -> 153.92468 | C3: ='P&L 2027'!C5 -> 384.81171 | D3: ='P&L 2027'!D5 -> 538.73639 | E3: ='P&L 2027'!E5 -> 538.73639 | F3: ='P&L 2027'!F5 -> 538.73639 | G3: ='P&L 2027'!G5 -> 538.73639 | H3: ='P&L 2027'!H5 -> 538.73639 | I3: ='P&L 2027'!I5 -> 615.69874 | ... O3: ='P&L 2027'!O5 -> 6195.4 | P3: =N3-O3 -> 1500.8342 | Q3: =(N3/O3)-1 -> 0.24224977 | S3: 7250.8 | T3: =N3-S3 -> 445.4342 | U3: =T3/S3 -> 0.061432421 | X3: E-comm | Y3: =SUM(P3) -> 1500.8342 | AB3: E-comm | AC3: =1012275179.86692/10^6 -> 1012.2752 | AD3: =Y3-AC3 -> 488.55902 | AE3: =AD3/AC3 -> 0.48263459
A4: E-commerce | B4: ='P&L 2027'!B6 -> 153.92468 | C4: ='P&L 2027'!C6 -> 384.81171 | D4: ='P&L 2027'!D6 -> 538.73639 | E4: ='P&L 2027'!E6 -> 538.73639 | F4: ='P&L 2027'!F6 -> 538.73639 | G4: ='P&L 2027'!G6 -> 538.73639 | H4: ='P&L 2027'!H6 -> 538.73639 | I4: ='P&L 2027'!I6 -> 615.69874 | ... O4: ='P&L 2027'!O6 -> 6195.4 | P4: =N4-O4 -> 1500.8342
A5: Online DMP | B5: ='P&L 2027'!B11 -> 32 | C5: ='P&L 2027'!C11 -> 80 | D5: ='P&L 2027'!D11 -> 112 | E5: ='P&L 2027'!E11 -> 112 | F5: ='P&L 2027'!F11 -> 112 | G5: ='P&L 2027'!G11 -> 112 | H5: ='P&L 2027'!H11 -> 112 | I5: ='P&L 2027'!I11 -> 128 | ... O5: ='P&L 2027'!O11 -> 987 | P5: =N5-O5 -> 613 | Q5: =(N5/O5)-1 -> 0.62107396 | S5: 1063.4449 | T5: =N5-S5 -> 536.55515 | U5: =T5/S5 -> 0.5045444 | X5: Offline | Y5: =SUM(P5,P10,P12,P18,P20) -> 2741.9517 | AB5: Offline | AC5: =1792170775.52776/10^6+675 -> 2467.1708 | AD5: =Y5-AC5 -> 274.7809 | AE5: =AD5/AC5 -> 0.1113749
A6: МК | B6: ='P&L 2027'!B12 -> 24.92632 | C6: ='P&L 2027'!C12 -> 62.3158 | D6: ='P&L 2027'!D12 -> 87.24212 | E6: ='P&L 2027'!E12 -> 87.24212 | F6: ='P&L 2027'!F12 -> 87.24212 | G6: ='P&L 2027'!G12 -> 87.24212 | H6: ='P&L 2027'!H12 -> 87.24212 | I6: ='P&L 2027'!I12 -> 99.70528 | ... O6: ='P&L 2027'!O12 -> 768.82118 | P6: =N6-O6 -> 477.49482
A7: ММ | B7: ='P&L 2027'!B13 -> 6.2505901 | C7: ='P&L 2027'!C13 -> 15.626475 | D7: ='P&L 2027'!D13 -> 21.877065 | E7: ='P&L 2027'!E13 -> 21.877065 | F7: ='P&L 2027'!F13 -> 21.877065 | G7: ='P&L 2027'!G13 -> 21.877065 | H7: ='P&L 2027'!H13 -> 21.877065 | I7: ='P&L 2027'!I13 -> 25.002361 | ... O7: ='P&L 2027'!O13 -> 192.79164 | P7: =N7-O7 -> 119.73787
A8: МЭ | B8: ='P&L 2027'!B14 -> 0.61413761 | C8: ='P&L 2027'!C14 -> 1.535344 | D8: ='P&L 2027'!D14 -> 2.1494816 | E8: ='P&L 2027'!E14 -> 2.1494816 | F8: ='P&L 2027'!F14 -> 2.1494816 | G8: ='P&L 2027'!G14 -> 2.1494816 | H8: ='P&L 2027'!H14 -> 2.1494816 | I8: ='P&L 2027'!I14 -> 2.4565504 | ... O8: ='P&L 2027'!O14 -> 18.942307 | P8: =N8-O8 -> 11.764574
A9: МС | B9: ='P&L 2027'!B15 -> 0.20895231 | C9: ='P&L 2027'!C15 -> 0.52238079 | D9: ='P&L 2027'!D15 -> 0.7313331 | E9: ='P&L 2027'!E15 -> 0.7313331 | F9: ='P&L 2027'!F15 -> 0.7313331 | G9: ='P&L 2027'!G15 -> 0.7313331 | H9: ='P&L 2027'!H15 -> 0.7313331 | I9: ='P&L 2027'!I15 -> 0.83580926 | ... O9: ='P&L 2027'!O15 -> 6.444873 | P9: =N9-O9 -> 4.0027428
A10: DMP | B10: ='P&L 2027'!B9 -> 3.74 | C10: ='P&L 2027'!C9 -> 9.35 | D10: ='P&L 2027'!D9 -> 13.09 | E10: ='P&L 2027'!E9 -> 13.09 | F10: ='P&L 2027'!F9 -> 13.09 | G10: ='P&L 2027'!G9 -> 13.09 | H10: ='P&L 2027'!H9 -> 13.09 | I10: ='P&L 2027'!I9 -> 14.96 | ... O10: ='P&L 2027'!O9 -> 102.4 | P10: =N10-O10 -> 84.6 | Q10: =(N10/O10)-1 -> 0.82617188 | S10: 124.68 | T10: =N10-S10 -> 62.32 | U10: =T10/S10 -> 0.49983959
A11: Без формата | B11: ='P&L 2027'!B10 -> 3.74 | C11: ='P&L 2027'!C10 -> 9.35 | D11: ='P&L 2027'!D10 -> 13.09 | E11: ='P&L 2027'!E10 -> 13.09 | F11: ='P&L 2027'!F10 -> 13.09 | G11: ='P&L 2027'!G10 -> 13.09 | H11: ='P&L 2027'!H10 -> 13.09 | I11: ='P&L 2027'!I10 -> 14.96 | ... O11: ='P&L 2027'!O10 -> 102.4 | P11: =N11-O11 -> 84.6
A12: Instore digital | B12: ='P&L 2027'!B16 -> 80.390907 | C12: ='P&L 2027'!C16 -> 200.98173 | D12: ='P&L 2027'!D16 -> 281.36817 | E12: ='P&L 2027'!E16 -> 281.35478 | F12: ='P&L 2027'!F16 -> 281.36817 | G12: ='P&L 2027'!G16 -> 281.36817 | H12: ='P&L 2027'!H16 -> 281.36817 | I12: ='P&L 2027'!I16 -> 321.5413 | ... O12: ='P&L 2027'!O16 -> 2446.0892 | P12: =N12-O12 -> 1573.4025 | Q12: =(N12/O12)-1 -> 0.64323186 | S12: 4509.1703 | T12: =N12-S12 -> -489.67856 | U12: =T12/S12 -> -0.10859615
A13: ММ | B13: ='P&L 2027'!B17 -> 54.868947 | C13: ='P&L 2027'!C17 -> 137.17542 | D13: ='P&L 2027'!D17 -> 192.04132 | E13: ='P&L 2027'!E17 -> 192.03217 | F13: ='P&L 2027'!F17 -> 192.04132 | G13: ='P&L 2027'!G17 -> 192.04132 | H13: ='P&L 2027'!H17 -> 192.04132 | I13: ='P&L 2027'!I17 -> 219.46055 | ... O13: ='P&L 2027'!O17 -> 1669.5214 | P13: =N13-O13 -> 1073.8894
A14: МЭ | B14: ='P&L 2027'!B18 -> 10.543305 | C14: ='P&L 2027'!C18 -> 26.358849 | D14: ='P&L 2027'!D18 -> 36.901569 | E14: ='P&L 2027'!E18 -> 36.899812 | F14: ='P&L 2027'!F18 -> 36.901569 | G14: ='P&L 2027'!G18 -> 36.901569 | H14: ='P&L 2027'!H18 -> 36.901569 | I14: ='P&L 2027'!I18 -> 42.170293 | ... O14: ='P&L 2027'!O18 -> 320.80576 | P14: =N14-O14 -> 206.35248
A15: МС | B15: ='P&L 2027'!B19 -> 4.7716856 | C15: ='P&L 2027'!C19 -> 11.929479 | D15: ='P&L 2027'!D19 -> 16.7009 | E15: ='P&L 2027'!E19 -> 16.700104 | F15: ='P&L 2027'!F19 -> 16.7009 | G15: ='P&L 2027'!G19 -> 16.7009 | H15: ='P&L 2027'!H19 -> 16.7009 | I15: ='P&L 2027'!I19 -> 19.085417 | ... O15: ='P&L 2027'!O19 -> 145.19016 | P15: =N15-O15 -> 93.390937
A16: МК | B16: ='P&L 2027'!B20 -> 7.8696434 | C16: ='P&L 2027'!C20 -> 19.674546 | D16: ='P&L 2027'!D20 -> 27.543752 | E16: ='P&L 2027'!E20 -> 27.54244 | F16: ='P&L 2027'!F20 -> 27.543752 | G16: ='P&L 2027'!G20 -> 27.543752 | H16: ='P&L 2027'!H20 -> 27.543752 | I16: ='P&L 2027'!I20 -> 31.476387 | ... O16: ='P&L 2027'!O20 -> 239.45308 | P16: =N16-O16 -> 154.02385
A17: МС Лайт | B17: ='P&L 2027'!B21 -> 2.3373256 | C17: ='P&L 2027'!C21 -> 5.8434438 | D17: ='P&L 2027'!D21 -> 8.1806395 | E17: ='P&L 2027'!E21 -> 8.1802499 | F17: ='P&L 2027'!F21 -> 8.1806395 | G17: ='P&L 2027'!G21 -> 8.1806395 | H17: ='P&L 2027'!H21 -> 8.1806395 | I17: ='P&L 2027'!I21 -> 9.348653 | ... O17: ='P&L 2027'!O21 -> 71.118826 | P17: =N17-O17 -> 45.745894
A18: Content factory отдельное ЮЛ | B18: ='P&L 2027'!B7 -> 4.266 | C18: ='P&L 2027'!C7 -> 10.665 | D18: ='P&L 2027'!D7 -> 14.931 | E18: ='P&L 2027'!E7 -> 14.931 | F18: ='P&L 2027'!F7 -> 14.931 | G18: ='P&L 2027'!G7 -> 14.931 | H18: ='P&L 2027'!H7 -> 14.931 | I18: ='P&L 2027'!I7 -> 17.064 | ... O18: ='P&L 2027'!O7 -> 0 | P18: =N18-O18 -> 213.3 | Q18: -
A19: Без формата | B19: ='P&L 2027'!B8 -> 4.266 | C19: ='P&L 2027'!C8 -> 10.665 | D19: ='P&L 2027'!D8 -> 14.931 | E19: ='P&L 2027'!E8 -> 14.931 | F19: ='P&L 2027'!F8 -> 14.931 | G19: ='P&L 2027'!G8 -> 14.931 | H19: ='P&L 2027'!H8 -> 14.931 | I19: ='P&L 2027'!I8 -> 17.064 | ... O19: ='P&L 2027'!O8 -> 0 | P19: =N19-O19 -> 213.3
A20: RMN (Brand budgets call) отдельное ЮЛ | B20: ='P&L 2027'!B22 -> 17.004183 | C20: ='P&L 2027'!C22 -> 42.510457 | D20: ='P&L 2027'!D22 -> 59.51464 | E20: ='P&L 2027'!E22 -> 59.51464 | F20: ='P&L 2027'!F22 -> 59.51464 | G20: ='P&L 2027'!G22 -> 59.51464 | H20: ='P&L 2027'!H22 -> 59.51464 | I20: ='P&L 2027'!I22 -> 68.016732 | ... O20: ='P&L 2027'!O22 -> 592.56 | P20: =N20-O20 -> 257.64914 | Q20: =(N20/O20)-1 -> 0.43480685 | S20: 0 | T20: =N20-S20 -> 850.20914
A21: Без формата | B21: ='P&L 2027'!B23 -> 17.004183 | C21: ='P&L 2027'!C23 -> 42.510457 | D21: ='P&L 2027'!D23 -> 59.51464 | E21: ='P&L 2027'!E23 -> 59.51464 | F21: ='P&L 2027'!F23 -> 59.51464 | G21: ='P&L 2027'!G23 -> 59.51464 | H21: ='P&L 2027'!H23 -> 59.51464 | I21: ='P&L 2027'!I23 -> 68.016732 | ... O21: ='P&L 2027'!O23 -> 592.56 | P21: =N21-O21 -> 257.64914
A22: Gross Revenue | B22: =SUM(B3,B5,B10,B12,B18,B20) -> 291.32577 | C22: =SUM(C3,C5,C10,C12,C18,C20) -> 728.3189 | D22: =SUM(D3,D5,D10,D12,D18,D20) -> 1019.6402 | E22: =SUM(E3,E5,E10,E12,E18,E20) -> 1019.6268 | F22: =SUM(F3,F5,F10,F12,F18,F20) -> 1019.6402 | G22: =SUM(G3,G5,G10,G12,G18,G20) -> 1019.6402 | H22: =SUM(H3,H5,H10,H12,H18,H20) -> 1019.6402 | I22: =SUM(I3,I5,I10,I12,I18,I20) -> 1165.2808 | ... O22: =SUM(O3,O5,O10,O12,O18,O20) -> 10323.449 | P22: =N22-O22 -> 4242.7859 | Q22: =(N22/O22)-1 -> 0.4109853 | S22: =SUM(S3:S20) -> 12948.095 | T22: =N22-S22 -> 1618.1399 | U22: =T22/S22 -> 0.12497127 | X22: Revenue increase YOY | Y22: =SUM(Y3:Y20) -> 4242.7859 | AB22: Revenue increase YOY | AC22: =AC3+AC5 -> 3479.446 | AD22: =Y22-AC22 -> 763.33991 | AE22: =AD22/AC22 -> 0.21938548
A23: COGS (расходы, привязанные к выручке) | B23: ='P&L 2027'!B28 -> -89.8693 | C23: ='P&L 2027'!C28 -> -125.27429 | D23: ='P&L 2027'!D28 -> -148.83773 | E23: ='P&L 2027'!E28 -> -152.62163 | F23: ='P&L 2027'!F28 -> -153.65103 | G23: ='P&L 2027'!G28 -> -154.55941 | H23: ='P&L 2027'!H28 -> -154.51273 | I23: ='P&L 2027'!I28 -> -164.49599 | ... O23: ='P&L 2027'!O28 -> -880.54 | P23: =N23-O23 -> -1090.526 | Q23: =(N23/O23)-1 -> 1.2384741 | S23: -1292.1891 | T23: =N23-S23 -> -678.87692 | U23: =T23/S23 -> 0.52536965 | X23: COGS | Y23: =N23 -> -1971.066 | AB23: COGS | AC23: =S23 -> -1292.1891 | AD23: =Y23-AC23 -> -678.87692 | AE23: =AD23/AC23 -> 0.52536965
A24: Net Revenue | B24: =B22+B23 -> 201.45647 | C24: =C22+C23 -> 603.04461 | D24: =D22+D23 -> 870.80248 | E24: =E22+E23 -> 867.00518 | F24: =F22+F23 -> 865.98918 | G24: =G22+G23 -> 865.0808 | H24: =H22+H23 -> 865.12748 | I24: =I22+I23 -> 1000.7848 | ... O24: =O22+O23 -> 9442.9092 | P24: =N24-O24 -> 3152.2599 | Q24: =(N24/O24)-1 -> 0.33382296 | S24: =S22+S23 -> 11655.906 | T24: =N24-S24 -> 939.26301 | U24: =T24/S24 -> 0.080582582 | X24: Net Revenue increase | Y24: =Y22+Y23 -> 2271.7199 | AB24: Net Revenue increase | AC24: =AC22+AC23 -> 2187.2569 | AD24: =Y24-AC24 -> 84.462989 | AE24: =AD24/AC24 -> 0.038615944
A25: PEX | B25: ='P&L 2027'!B37 -> -113.96405 | C25: ='P&L 2027'!C37 -> -116.10616 | D25: ='P&L 2027'!D37 -> -116.71057 | E25: ='P&L 2027'!E37 -> -118.66284 | F25: ='P&L 2027'!F37 -> -120.87805 | G25: ='P&L 2027'!G37 -> -117.8386 | H25: ='P&L 2027'!H37 -> -120.78408 | I25: ='P&L 2027'!I37 -> -102.88362 | ... O25: ='P&L 2027'!O37 -> -1120.0714 | P25: =N25-O25 -> -316.2915 | Q25: =(N25/O25)-1 -> 0.28238511 | S25: -1478.5147 | T25: =N25-S25 -> 42.151724 | U25: =T25/S25 -> -0.028509507 | X25: PEX | Y25: =N25 -> -1436.3629 | AB25: PEX | AC25: =S25 -> -1478.5147 | AD25: =Y25-AC25 -> 42.151724 | AE25: =AD25/AC25 -> -0.028509507
A26: Other PEX | B26: ='P&L 2027'!B48 -> -1.1561945 | C26: ='P&L 2027'!C48 -> -5.1511945 | D26: ='P&L 2027'!D48 -> -1.8032845 | E26: ='P&L 2027'!E48 -> -12.253285 | F26: ='P&L 2027'!F48 -> -1.6682845 | G26: ='P&L 2027'!G48 -> -1.6632845 | H26: ='P&L 2027'!H48 -> -7.8032845 | I26: ='P&L 2027'!I48 -> -2.0029545 | ... O26: ='P&L 2027'!O48 -> -32.7 | P26: =N26-O26 -> -7.5864319 | Q26: =(N26/O26)-1 -> 0.23200098 | S26: -26.209876 | T26: =N26-S26 -> -14.076556 | U26: =T26/S26 -> 0.5370707 | X26: Other PEX | Y26: =N26 -> -40.286432 | AB26: Other PEX | AC26: =S26 -> -26.209876 | AD26: =Y26-AC26 -> -14.076556 | AE26: =AD26/AC26 -> 0.5370707
A27: Marketing | B27: ='P&L 2027'!B53 -> -5.9676923 | C27: ='P&L 2027'!C53 -> -10.317692 | D27: ='P&L 2027'!D53 -> -9.5426923 | E27: ='P&L 2027'!E53 -> -7.9676923 | F27: ='P&L 2027'!F53 -> -6.1676923 | G27: ='P&L 2027'!G53 -> -7.3426923 | H27: ='P&L 2027'!H53 -> -10.308677 | I27: ='P&L 2027'!I53 -> -7.6586771 | ... O27: ='P&L 2027'!O53 -> -55.25 | P27: =N27-O27 -> -45.408216 | Q27: =(N27/O27)-1 -> 0.82186816 | S27: -37.5 | T27: =N27-S27 -> -63.158216 | U27: =T27/S27 -> 1.6842191 | X27: Marketing | Y27: =N27 -> -100.65822 | AB27: Marketing | AC27: =S27 -> -37.5 | AD27: =Y27-AC27 -> -63.158216 | AE27: =AD27/AC27 -> 1.6842191
A28: Other OPEX | B28: ='P&L 2027'!B64 -> -2.4452511 | C28: ='P&L 2027'!C64 -> -5.3256591 | D28: ='P&L 2027'!D64 -> -7.245879 | E28: ='P&L 2027'!E64 -> -7.2457852 | F28: ='P&L 2027'!F64 -> -7.245879 | G28: ='P&L 2027'!G64 -> -7.245879 | H28: ='P&L 2027'!H64 -> -7.245879 | I28: ='P&L 2027'!I64 -> -8.2058482 | ... O28: ='P&L 2027'!O64 -> -91.6 | P28: =N28-O28 -> -10.712182 | Q28: =(N28/O28)-1 -> 0.11694522 | S28: -98.201769 | T28: =N28-S28 -> -4.1104132 | U28: =T28/S28 -> 0.041856815 | X28: Other OPEX | Y28: =N28 -> -102.31218 | AB28: Other OPEX | AC28: =S28 -> -98.201769 | AD28: =Y28-AC28 -> -4.1104132 | AE28: =AD28/AC28 -> 0.041856815
A29: IT | B29: ='P&L 2027'!B55 -> -6.4490727 | C29: ='P&L 2027'!C55 -> -6.4490727 | D29: ='P&L 2027'!D55 -> -6.8490727 | E29: ='P&L 2027'!E55 -> -6.6490727 | F29: ='P&L 2027'!F55 -> -7.1490727 | G29: ='P&L 2027'!G55 -> -7.0995797 | H29: ='P&L 2027'!H55 -> -7.0420068 | I29: ='P&L 2027'!I55 -> -7.309943 | ... O29: ='P&L 2027'!O55 -> -58.6 | P29: =N29-O29 -> -33.500557 | Q29: =(N29/O29)-1 -> 0.57168186 | S29: -62.06 | T29: =N29-S29 -> -30.040557 | U29: =T29/S29 -> 0.48405667 | X29: IT | Y29: =N29 -> -92.100557 | AB29: IT | AC29: =S29 -> -62.06 | AD29: =Y29-AC29 -> -30.040557 | AE29: =AD29/AC29 -> 0.48405667
A30: OPEX | B30: =SUM(B25:B29) -> -129.98226 | C30: =SUM(C25:C29) -> -143.34978 | D30: =SUM(D25:D29) -> -142.1515 | E30: =SUM(E25:E29) -> -152.77868 | F30: =SUM(F25:F29) -> -143.10898 | G30: =SUM(G25:G29) -> -141.19004 | H30: =SUM(H25:H29) -> -153.18393 | I30: =SUM(I25:I29) -> -128.06104 | ... O30: =SUM(O25:O29) -> -1358.2214 | P30: =N30-O30 -> -413.49888 | Q30: =(N30/O30)-1 -> 0.30444143 | S30: =SUM(S25:S29) -> -1702.4863 | T30: =N30-S30 -> -69.234018 | U30: =T30/S30 -> 0.040666417 | W30: - | X30: OPEX | Y30: =SUM(Y25:Y29) -> -1771.7203 | AB30: OPEX | AC30: =SUM(AC25:AC29) -> -1702.4863 | AD30: =Y30-AC30 -> -69.234018 | AE30: =AD30/AC30 -> 0.040666417
A31: EBITDA | B31: =B30+B24 -> 71.474217 | C31: =C30+C24 -> 459.69482 | D31: =D30+D24 -> 728.65098 | E31: =E30+E24 -> 714.2265 | F31: =F30+F24 -> 722.8802 | G31: =G30+G24 -> 723.89076 | H31: =H30+H24 -> 711.94356 | I31: =I30+I24 -> 872.72373 | ... O31: =O30+O24 -> 8084.6878 | P31: =N31-O31 -> 2738.761 | Q31: =(N31/O31)-1 -> 0.33875903 | S31: =S30+S24 -> 9953.4198 | T31: =N31-S31 -> 870.02899 | U31: =T31/S31 -> 0.087410057 | X31: EBITDA | Y31: =Y24+Y30 -> 499.99955 | AB31: EBITDA | AC31: =AC30+AC24 -> 484.77058 | AD31: =Y31-AC31 -> 15.228971 | AE31: =AD31/AC31 -> 0.0314148
A32: Разработка рекламной платформы | B32: ='P&L 2027_AdvInventory'!B54 -> -42.458922 | C32: ='P&L 2027_AdvInventory'!C54 -> -43.04558 | D32: ='P&L 2027_AdvInventory'!D54 -> -44.505901 | E32: ='P&L 2027_AdvInventory'!E54 -> -44.369799 | F32: ='P&L 2027_AdvInventory'!F54 -> -44.528812 | G32: ='P&L 2027_AdvInventory'!G54 -> -44.182905 | H32: ='P&L 2027_AdvInventory'!H54 -> -47.108845 | I32: ='P&L 2027_AdvInventory'!I54 -> -46.623045 | ... O32: ='P&L 2027_AdvInventory'!O54 -> -447.2 | P32: =N32-O32 -> -93.833873 | Q32: =(N32/O32)-1 -> 0.2098253
A33: Проекты Digital Instore (оснащение ТТ) | B33: ='P&L 2027_AdvInventory'!B55 -> 0 | C33: ='P&L 2027_AdvInventory'!C55 -> 0 | D33: ='P&L 2027_AdvInventory'!D55 -> 0 | E33: ='P&L 2027_AdvInventory'!E55 -> -10.23056 | F33: ='P&L 2027_AdvInventory'!F55 -> -18.36096 | G33: ='P&L 2027_AdvInventory'!G55 -> -52.572558 | H33: ='P&L 2027_AdvInventory'!H55 -> -45.678337 | I33: ='P&L 2027_AdvInventory'!I55 -> -56.619953 | ... O33: ='P&L 2027_AdvInventory'!O55 -> -732.4 | P33: =N33-O33 -> 122.79413 | Q33: =(N33/O33)-1 -> -0.16765993
A34: CAPEX | B34: =SUM(B32:B33) -> -42.458922 | C34: =SUM(C32:C33) -> -43.04558 | D34: =SUM(D32:D33) -> -44.505901 | E34: =SUM(E32:E33) -> -54.600359 | F34: =SUM(F32:F33) -> -62.889772 | G34: =SUM(G32:G33) -> -96.755463 | H34: =SUM(H32:H33) -> -92.787183 | I34: =SUM(I32:I33) -> -103.243 | ... O34: =SUM(O32:O33) -> -1179.6 | P34: =N34-O34 -> 28.960258 | Q34: =(N34/O34)-1 -> -0.024550914 | S34: -1242.3503 | T34: =N34-S34 -> 91.71053 | U34: =T34/S34 -> -0.073820187 | X34: =A34 -> CAPEX | Y34: =N34 -> -1150.6397 | AB34: CAPEX | AC34: =S34 -> -1242.3503 | AD34: =Y34-AC34 -> 91.71053 | AE34: =AD34/AC34 -> -0.073820187
A35: FCF | B35: =B34+B31 -> 29.015294 | C35: =C34+C31 -> 416.64924 | D35: =D34+D31 -> 684.14508 | E35: =E34+E31 -> 659.62614 | F35: =F34+F31 -> 659.99043 | G35: =G34+G31 -> 627.1353 | H35: =H34+H31 -> 619.15637 | I35: =I34+I31 -> 769.48073 | ... O35: =O34+O31 -> 6905.0878 | P35: =N35-O35 -> 2767.7212 | Q35: =(N35/O35)-1 -> 0.40082347 | S35: =S34+S31 -> 8711.0695 | T35: =N35-S35 -> 961.73952 | U35: =T35/S35 -> 0.1104043 | X35: FCF | Y35: =Y31+Y34 -> -650.6402 | AB35: FCF | AC35: =AC34+AC31 -> -757.5797 | AD35: =Y35-AC35 -> 106.9395 | AE35: =AD35/AC35 -> -0.14115941
A37: Revenue М+ | B37: ='P&L 2027'!B73 -> 337.89281 | C37: ='P&L 2027'!C73 -> 365.73325 | D37: ='P&L 2027'!D73 -> 377.3919 | E37: ='P&L 2027'!E73 -> 394.58185 | F37: ='P&L 2027'!F73 -> 414.44746 | G37: ='P&L 2027'!G73 -> 435.07252 | H37: ='P&L 2027'!H73 -> 455.65159 | I37: ='P&L 2027'!I73 -> 478.67974 | ... O37: ='P&L 2027'!O73 -> 3007 | P37: =N37-O37 -> 2437.4019 | Q37: =(N37/O37)-1 -> 0.81057595 | AC37: =AC31-500 -> -15.229425
A40: Справочно экономия CAPEX ГК благодаря собственной разработке AdTech
N41: CAPEX adj. | O41: Add. OPEX | P41: Total saving
A42: Cubic | N42: -28.46873 | O42: 14.234365 | P42: =SUM(N42:O42) -> -14.234365
A43: InAppStory | N43: -7.3794 | O43: 0 | P43: =SUM(N43:O43) -> -7.3794
...

Sheet P&L 2027
A1: P&L AdTech 2027 - BOTTOM-UP | Q1: Описание: bottom-up P&L AdTech 2027 по месяцам, млн ₽ без НДС. Логика: выручка - из листов направлений (APP = Медиа + Перформанс, Content factory, DMP, In-store; RMN), логика по распределению на форматы см. на листе «RevSplit»; расходы - из листа «Расходы»
A2: Млн руб. без НДС.
B3: =B24/$N$24 -> 0.020000074 | C3: =C24/$N$24 -> 0.050000491 | D3: =D24/$N$24 -> 0.070000258 | E3: =E24/$N$24 -> 0.069999338 | F3: =F24/$N$24 -> 0.070000258 | G3: =G24/$N$24 -> 0.070000258 | H3: =H24/$N$24 -> 0.070000258 | I3: =I24/$N$24 -> 0.079998761 | ... N3: =N24/$N$24 -> 1
A4: Статья | B4: янв | C4: фев | D4: мар | E4: апр | F4: май | G4: июн | H4: июл | I4: авг | J4: сен | K4: окт | L4: ноя | M4: дек | N4: 2027 | O4: 2026
A5: APP | B5: =B6 -> 153.92468 | C5: =C6 -> 384.81171 | D5: =D6 -> 538.73639 | E5: =E6 -> 538.73639 | F5: =F6 -> 538.73639 | G5: =G6 -> 538.73639 | H5: =H6 -> 538.73639 | I5: =I6 -> 615.69874 | ... O5: =O6 -> 6195.4 | P5: =IFERROR(N5/O5-1,"") -> 0.24224977
A6: =RevSplit!W5 -> E-commerce | B6: =RevSplit!X5 -> 153.92468 | C6: =RevSplit!Y5 -> 384.81171 | D6: =RevSplit!Z5 -> 538.73639 | E6: =RevSplit!AA5 -> 538.73639 | F6: =RevSplit!AB5 -> 538.73639 | G6: =RevSplit!AC5 -> 538.73639 | H6: =RevSplit!AD5 -> 538.73639 | ... M6: =RevSplit!AI5 -> 1308.3598 | N6: =SUM(B6:M6) -> 7696.2342 | O6: =RevSplit!AK5 -> 6195.4
A7: Content factory | B7: =B8 -> 4.266 | C7: =C8 -> 10.665 | D7: =D8 -> 14.931 | E7: =E8 -> 14.931 | F7: =F8 -> 14.931 | G7: =G8 -> 14.931 | H7: =H8 -> 14.931 | I7: =I8 -> 17.064 | ... O7: =O8 -> 0 | P7: =IFERROR(N7/O7-1,"")
A8: Без формата | B8: =RevSplit!F6 -> 4.266 | C8: =RevSplit!G6 -> 10.665 | D8: =RevSplit!H6 -> 14.931 | E8: =RevSplit!I6 -> 14.931 | F8: =RevSplit!J6 -> 14.931 | G8: =RevSplit!K6 -> 14.931 | H8: =RevSplit!L6 -> 14.931 | I8: =RevSplit!M6 -> 17.064 | ... M8: =RevSplit!Q6 -> 36.261 | N8: =SUM(B8:M8) -> 213.3 | O8: =RevSplit!S6 -> 0
A9: DMP+ Analitycs | B9: =B10 -> 3.74 | C9: =C10 -> 9.35 | D9: =D10 -> 13.09 | E9: =E10 -> 13.09 | F9: =F10 -> 13.09 | G9: =G10 -> 13.09 | H9: =H10 -> 13.09 | I9: =I10 -> 14.96 | ... O9: =O10 -> 102.4 | P9: =IFERROR(N9/O9-1,"") -> 0.82617188
A10: Без формата | B10: =RevSplit!F7 -> 3.74 | C10: =RevSplit!G7 -> 9.35 | D10: =RevSplit!H7 -> 13.09 | E10: =RevSplit!I7 -> 13.09 | F10: =RevSplit!J7 -> 13.09 | G10: =RevSplit!K7 -> 13.09 | H10: =RevSplit!L7 -> 13.09 | I10: =RevSplit!M7 -> 14.96 | ... M10: =RevSplit!Q7 -> 31.79 | N10: =SUM(B10:M10) -> 187 | O10: =RevSplit!S7 -> 102.4
A11: DMP+Online | B11: =SUM(B12:B15) -> 32 | C11: =SUM(C12:C15) -> 80 | D11: =SUM(D12:D15) -> 112 | E11: =SUM(E12:E15) -> 112 | F11: =SUM(F12:F15) -> 112 | G11: =SUM(G12:G15) -> 112 | H11: =SUM(H12:H15) -> 112 | I11: =SUM(I12:I15) -> 128 | ... O11: =SUM(O12:O15) -> 987 | P11: =IFERROR(N11/O11-1,"") -> 0.62107396
A12: МК | B12: =RevSplit!F21 -> 24.92632 | C12: =RevSplit!G21 -> 62.3158 | D12: =RevSplit!H21 -> 87.24212 | E12: =RevSplit!I21 -> 87.24212 | F12: =RevSplit!J21 -> 87.24212 | G12: =RevSplit!K21 -> 87.24212 | H12: =RevSplit!L21 -> 87.24212 | I12: =RevSplit!M21 -> 99.70528 | ... M12: =RevSplit!Q21 -> 211.87372 | N12: =SUM(B12:M12) -> 1246.316 | O12: =RevSplit!S21 -> 768.82118
A13: ММ | B13: =RevSplit!F22 -> 6.2505901 | C13: =RevSplit!G22 -> 15.626475 | D13: =RevSplit!H22 -> 21.877065 | E13: =RevSplit!I22 -> 21.877065 | F13: =RevSplit!J22 -> 21.877065 | G13: =RevSplit!K22 -> 21.877065 | H13: =RevSplit!L22 -> 21.877065 | I13: =RevSplit!M22 -> 25.002361 | ... M13: =RevSplit!Q22 -> 53.130016 | N13: =SUM(B13:M13) -> 312.52951 | O13: =RevSplit!S22 -> 192.79164
A14: МЭ | B14: =RevSplit!F23 -> 0.61413761 | C14: =RevSplit!G23 -> 1.535344 | D14: =RevSplit!H23 -> 2.1494816 | E14: =RevSplit!I23 -> 2.1494816 | F14: =RevSplit!J23 -> 2.1494816 | G14: =RevSplit!K23 -> 2.1494816 | H14: =RevSplit!L23 -> 2.1494816 | I14: =RevSplit!M23 -> 2.4565504 | ... M14: =RevSplit!Q23 -> 5.2201697 | N14: =SUM(B14:M14) -> 30.706881 | O14: =RevSplit!S23 -> 18.942307
A15: МС | B15: =RevSplit!F24 -> 0.20895231 | C15: =RevSplit!G24 -> 0.52238079 | D15: =RevSplit!H24 -> 0.7313331 | E15: =RevSplit!I24 -> 0.7313331 | F15: =RevSplit!J24 -> 0.7313331 | G15: =RevSplit!K24 -> 0.7313331 | H15: =RevSplit!L24 -> 0.7313331 | I15: =RevSplit!M24 -> 0.83580926 | ... M15: =RevSplit!Q24 -> 1.7760947 | N15: =SUM(B15:M15) -> 10.447616 | O15: =RevSplit!S24 -> 6.444873
A16: Instore digital | B16: =SUM(B17:B21) -> 80.390907 | C16: =SUM(C17:C21) -> 200.98173 | D16: =SUM(D17:D21) -> 281.36817 | E16: =SUM(E17:E21) -> 281.35478 | F16: =SUM(F17:F21) -> 281.36817 | G16: =SUM(G17:G21) -> 281.36817 | H16: =SUM(H17:H21) -> 281.36817 | I16: =SUM(I17:I21) -> 321.5413 | ... O16: =SUM(O17:O21) -> 2446.0892 | P16: =IFERROR(N16/O16-1,"") -> 0.64323186
A17: ММ | B17: =RevSplit!F30 -> 54.868947 | C17: =RevSplit!G30 -> 137.17542 | D17: =RevSplit!H30 -> 192.04132 | E17: =RevSplit!I30 -> 192.03217 | F17: =RevSplit!J30 -> 192.04132 | G17: =RevSplit!K30 -> 192.04132 | H17: =RevSplit!L30 -> 192.04132 | I17: =RevSplit!M30 -> 219.46055 | ... M17: =RevSplit!Q30 -> 466.38605 | N17: =SUM(B17:M17) -> 2743.4108 | O17: =RevSplit!S30 -> 1669.5214
A18: МЭ | B18: =RevSplit!F31 -> 10.543305 | C18: =RevSplit!G31 -> 26.358849 | D18: =RevSplit!H31 -> 36.901569 | E18: =RevSplit!I31 -> 36.899812 | F18: =RevSplit!J31 -> 36.901569 | G18: =RevSplit!K31 -> 36.901569 | H18: =RevSplit!L31 -> 36.901569 | I18: =RevSplit!M31 -> 42.170293 | ... M18: =RevSplit!Q31 -> 89.618096 | N18: =SUM(B18:M18) -> 527.15824 | O18: =RevSplit!S31 -> 320.80576
A19: МС | B19: =RevSplit!F32 -> 4.7716856 | C19: =RevSplit!G32 -> 11.929479 | D19: =RevSplit!H32 -> 16.7009 | E19: =RevSplit!I32 -> 16.700104 | F19: =RevSplit!J32 -> 16.7009 | G19: =RevSplit!K32 -> 16.7009 | H19: =RevSplit!L32 -> 16.7009 | I19: =RevSplit!M32 -> 19.085417 | ... M19: =RevSplit!Q32 -> 40.559327 | N19: =SUM(B19:M19) -> 238.5811 | O19: =RevSplit!S32 -> 145.19016
A20: МК | B20: =RevSplit!F33 -> 7.8696434 | C20: =RevSplit!G33 -> 19.674546 | D20: =RevSplit!H33 -> 27.543752 | E20: =RevSplit!I33 -> 27.54244 | F20: =RevSplit!J33 -> 27.543752 | G20: =RevSplit!K33 -> 27.543752 | H20: =RevSplit!L33 -> 27.543752 | I20: =RevSplit!M33 -> 31.476387 | ... M20: =RevSplit!Q33 -> 66.891969 | N20: =SUM(B20:M20) -> 393.47692 | O20: =RevSplit!S33 -> 239.45308
A21: МС Лайт | B21: =RevSplit!F34 -> 2.3373256 | C21: =RevSplit!G34 -> 5.8434438 | D21: =RevSplit!H34 -> 8.1806395 | E21: =RevSplit!I34 -> 8.1802499 | F21: =RevSplit!J34 -> 8.1806395 | G21: =RevSplit!K34 -> 8.1806395 | H21: =RevSplit!L34 -> 8.1806395 | I21: =RevSplit!M34 -> 9.348653 | ... M21: =RevSplit!Q34 -> 19.867267 | N21: =SUM(B21:M21) -> 116.86472 | O21: =RevSplit!S34 -> 71.118826
A22: RMN (Brand budgets call) | B22: =B23 -> 17.004183 | C22: =C23 -> 42.510457 | D22: =D23 -> 59.51464 | E22: =E23 -> 59.51464 | F22: =F23 -> 59.51464 | G22: =G23 -> 59.51464 | H22: =H23 -> 59.51464 | I22: =I23 -> 68.016732 | ... O22: =O23 -> 592.56 | P22: =IFERROR(N22/O22-1,"") -> 0.43480685
A23: Без формата | B23: =RevSplit!F10 -> 17.004183 | C23: =RevSplit!G10 -> 42.510457 | D23: =RevSplit!H10 -> 59.51464 | E23: =RevSplit!I10 -> 59.51464 | F23: =RevSplit!J10 -> 59.51464 | G23: =RevSplit!K10 -> 59.51464 | H23: =RevSplit!L10 -> 59.51464 | I23: =RevSplit!M10 -> 68.016732 | ... M23: =RevSplit!Q10 -> 144.53555 | N23: =SUM(B23:M23) -> 850.20914 | O23: =RevSplit!S10 -> 592.56
A24: Gross Revenue | B24: =SUM(B5,B7,B9,B11,B16,B22) -> 291.32577 | C24: =SUM(C5,C7,C9,C11,C16,C22) -> 728.3189 | D24: =SUM(D5,D7,D9,D11,D16,D22) -> 1019.6402 | E24: =SUM(E5,E7,E9,E11,E16,E22) -> 1019.6268 | F24: =SUM(F5,F7,F9,F11,F16,F22) -> 1019.6402 | G24: =SUM(G5,G7,G9,G11,G16,G22) -> 1019.6402 | H24: =SUM(H5,H7,H9,H11,H16,H22) -> 1019.6402 | I24: =SUM(I5,I7,I9,I11,I16,I22) -> 1165.2808 | ... O24: =SUM(O5,O7,O9,O11,O16,O22) -> 10323.449
A25: Расходы на маркетинг в сети интернет | B25: =Расходы!C26 -> -19.3793 | C25: =Расходы!D26 -> -51.604294 | D25: =Расходы!E26 -> -68.277733 | E25: =Расходы!F26 -> -71.584631 | F25: =Расходы!G26 -> -72.296031 | G25: =Расходы!H26 -> -72.409411 | H25: =Расходы!I26 -> -72.362725 | I25: =Расходы!J26 -> -81.232995 | ... M25: =Расходы!N26 -> -163.80337 | N25: =SUM(B25:M25) -> -1000 | O25: =Расходы!P26 -> -510.54
A26: Вознаграждения креаторам | B26: =Расходы!C27 -> -4.24 | C26: =Расходы!D27 -> -7.42 | D26: =Расходы!E27 -> -14.31 | E26: =Расходы!F27 -> -14.787 | F26: =Расходы!G27 -> -15.105 | G26: =Расходы!H27 -> -15.9 | H26: =Расходы!I27 -> -15.9 | I26: =Расходы!J27 -> -17.013 | ... M26: =Расходы!N27 -> -19.08 | N26: =SUM(B26:M26) -> -176.066 | O26: -15.6
A27: Вознаграждения рекламным агентствам | B27: =Расходы!C28 -> -66.25 | C27: =Расходы!D28 -> -66.25 | D27: =Расходы!E28 -> -66.25 | E27: =Расходы!F28 -> -66.25 | F27: =Расходы!G28 -> -66.25 | G27: =Расходы!H28 -> -66.25 | H27: =Расходы!I28 -> -66.25 | I27: =Расходы!J28 -> -66.25 | ... M27: =Расходы!N28 -> -66.25 | N27: =SUM(B27:M27) -> -795 | O27: =Расходы!P28 -> -354.4
A28: COGS (расходы, привязанные к выручке) | B28: =SUM(B25:B27) -> -89.8693 | C28: =SUM(C25:C27) -> -125.27429 | D28: =SUM(D25:D27) -> -148.83773 | E28: =SUM(E25:E27) -> -152.62163 | F28: =SUM(F25:F27) -> -153.65103 | G28: =SUM(G25:G27) -> -154.55941 | H28: =SUM(H25:H27) -> -154.51273 | I28: =SUM(I25:I27) -> -164.49599 | ... M28: =SUM(M25:M27) -> -249.13337 | N28: =SUM(B28:M28) -> -1971.066 | O28: =SUM(O25:O27) -> -880.54
A29: Net Revenue | B29: =B24+B28 -> 201.45647 | C29: =C24+C28 -> 603.04461 | D29: =D24+D28 -> 870.80248 | E29: =E24+E28 -> 867.00518 | F29: =F24+F28 -> 865.98918 | G29: =G24+G28 -> 865.0808 | H29: =H24+H28 -> 865.12748 | I29: =I24+I28 -> 1000.7848 | ... M29: =M24+M28 -> 2227.1357 | N29: =SUM(B29:M29) -> 12595.169 | O29: =O24+O28 -> 9442.9092
A30: Налоги и взносы, связанные с расходами на оплату труда (ФОТ) | B30: =Расходы!C3 -> -20.502132 | C30: =Расходы!D3 -> -20.887499 | D30: =Расходы!E3 -> -20.996231 | E30: =Расходы!F3 -> -21.347445 | F30: =Расходы!G3 -> -21.745961 | G30: =Расходы!H3 -> -21.199164 | H30: =Расходы!I3 -> -21.729056 | I30: =Расходы!J3 -> -18.508763 | ... M30: =Расходы!N3 -> -23.873296 | N30: =SUM(B30:M30) -> -258.40169 | O30: =Расходы!P3 -> -201.50085
A31: Индексация | B31: =Расходы!C4 -> 0 | C31: =Расходы!D4 -> 0 | D31: =Расходы!E4 -> 0 | E31: =Расходы!F4 -> 0 | F31: =Расходы!G4 -> 0 | G31: =Расходы!H4 -> 0 | H31: =Расходы!I4 -> 0 | I31: =Расходы!J4 -> 0 | ... M31: =Расходы!N4 -> 0 | N31: =SUM(B31:M31) -> 0 | O31: =Расходы!P4 -> 0
A32: Оплата труда - постоянная часть | B32: =Расходы!C5 -> -71.250322 | C32: =Расходы!D5 -> -72.589574 | D32: =Расходы!E5 -> -72.967448 | E32: =Расходы!F5 -> -74.188009 | F32: =Расходы!G5 -> -75.572956 | G32: =Расходы!H5 -> -73.672694 | H32: =Расходы!I5 -> -75.514206 | I32: =Расходы!J5 -> -64.322839 | ... M32: =Расходы!N5 -> -82.966006 | N32: =SUM(B32:M32) -> -898.01411 | O32: =Расходы!P5 -> -700.26866
A33: Оплата труда - премии | B33: =Расходы!C6 -> -2.6895515 | C33: =Расходы!D6 -> -2.7401055 | D33: =Расходы!E6 -> -2.7543694 | E33: =Расходы!F6 -> -2.8004431 | F33: =Расходы!G6 -> -2.852722 | G33: =Расходы!H6 -> -2.780991 | H33: =Расходы!I6 -> -2.8505043 | I33: =Расходы!J6 -> -2.4280534 | ... M33: =Расходы!N6 -> -3.1317942 | N33: =SUM(B33:M33) -> -33.898165 | O33: =Расходы!P6 -> -26.433686
A34: Оплата труда - отпускные | B34: =Расходы!C7 -> -4.6155439 | C34: =Расходы!D7 -> -4.7022997 | D34: =Расходы!E7 -> -4.7267781 | E34: =Расходы!F7 -> -4.8058451 | F34: =Расходы!G7 -> -4.895561 | G34: =Расходы!H7 -> -4.7724634 | H34: =Расходы!I7 -> -4.8917552 | I34: =Расходы!J7 -> -4.1667866 | ... M34: =Расходы!N7 -> -5.3744774 | N34: =SUM(B34:M34) -> -58.172699 | O34: =Расходы!P7 -> -45.362893
A35: Начисление резерва STI 100%, годовой бонус | B35: =Расходы!C8 -> -11.555954 | C35: =Расходы!D8 -> -11.773165 | D35: =Расходы!E8 -> -11.834452 | E35: =Расходы!F8 -> -12.032412 | F35: =Расходы!G8 -> -12.257034 | G35: =Расходы!H8 -> -11.948834 | H35: =Расходы!I8 -> -12.247506 | I35: =Расходы!J8 -> -10.432399 | ... M35: =Расходы!N8 -> -13.456099 | N35: =SUM(B35:M35) -> -145.6472 | O35: =Расходы!P8 -> -113.57524
A36: Начисление резерва STI 100%, квартальные бонусы | B36: =Расходы!C9 -> -3.350543 | C36: =Расходы!D9 -> -3.4135212 | D36: =Расходы!E9 -> -3.4312907 | E36: =Расходы!F9 -> -3.4886876 | F36: =Расходы!G9 -> -3.5538146 | G36: =Расходы!H9 -> -3.4644549 | H36: =Расходы!I9 -> -3.5510519 | I36: =Расходы!J9 -> -3.0247784 | ... M36: =Расходы!N9 -> -3.9014725 | N36: =SUM(B36:M36) -> -42.22907 | O36: =Расходы!P9 -> -32.9301
A37: PEX | B37: =SUM(B30:B36) -> -113.96405 | C37: =SUM(C30:C36) -> -116.10616 | D37: =SUM(D30:D36) -> -116.71057 | E37: =SUM(E30:E36) -> -118.66284 | F37: =SUM(F30:F36) -> -120.87805 | G37: =SUM(G30:G36) -> -117.8386 | H37: =SUM(H30:H36) -> -120.78408 | I37: =SUM(I30:I36) -> -102.88362 | ... M37: =SUM(M30:M36) -> -132.70314 | N37: =SUM(B37:M37) -> -1436.3629 | O37: =SUM(O30:O36) -> -1120.0714
A38: Материальная помощь | B38: =Расходы!C11 -> -0.005 | C38: =Расходы!D11 -> 0 | D38: =Расходы!E11 -> -0.005 | E38: =Расходы!F11 -> -0.005 | F38: =Расходы!G11 -> -0.005 | G38: =Расходы!H11 -> 0 | H38: =Расходы!I11 -> -0.005 | I38: =Расходы!J11 -> 0 | ... M38: =Расходы!N11 -> -0.005 | N38: =SUM(B38:M38) -> -0.04 | O38: =Расходы!P11 -> -0.4
A39: Затраты на корп. мероприятие кроме проезда и проживания | B39: =Расходы!C12 -> -0.375 | C39: =Расходы!D12 -> -0.375 | D39: =Расходы!E12 -> -0.51 | E39: =Расходы!F12 -> -0.375 | F39: =Расходы!G12 -> -0.375 | G39: =Расходы!H12 -> -0.375 | H39: =Расходы!I12 -> -0.51 | I39: =Расходы!J12 -> -0.375 | ... M39: =Расходы!N12 -> -0.375 | N39: =SUM(B39:M39) -> -4.77 | O39: =Расходы!P12 -> -3
A40: ДМС и НС | B40: =Расходы!C13 -> -0.86919813 | C40: =Расходы!D13 -> -0.86919813 | D40: =Расходы!E13 -> -0.86919813 | E40: =Расходы!F13 -> -0.86919813 | F40: =Расходы!G13 -> -0.86919813 | G40: =Расходы!H13 -> -0.86919813 | H40: =Расходы!I13 -> -0.86919813 | I40: =Расходы!J13 -> -0.86919813 | ... M40: =Расходы!N13 -> -0.97250298 | N40: =SUM(B40:M40) -> -10.546904 | O40: =Расходы!P13 -> -6.5
...

Sheet P&L 2027_AdvInventory
A1: P&L AdTech 2027 - BOTTOM-UP Advertising Inventory | Q1: Описание: bottom-up P&L AdTech 2027 по месяцам, млн ₽ без НДС. Логика: выручка - из листов направлений (APP = Медиа + Перформанс, Content factory, DMP, In-store; RMN); расходы - из листа «Расходы»
A2: Млн руб. без НДС.
A4: Статья | B4: янв | C4: фев | D4: мар | E4: апр | F4: май | G4: июн | H4: июл | I4: авг | J4: сен | K4: окт | L4: ноя | M4: дек | N4: 2027 | O4: 2026
A5: APP | B5: ='APP Медиа'!C54+'APP Перформанс'!C24 -> 153.92468 | C5: ='APP Медиа'!D54+'APP Перформанс'!D24 -> 384.81171 | D5: ='APP Медиа'!E54+'APP Перформанс'!E24 -> 538.73639 | E5: ='APP Медиа'!F54+'APP Перформанс'!F24 -> 538.73639 | F5: ='APP Медиа'!G54+'APP Перформанс'!G24 -> 538.73639 | G5: ='APP Медиа'!H54+'APP Перформанс'!H24 -> 538.73639 | H5: ='APP Медиа'!I54+'APP Перформанс'!I24 -> 538.73639 | I5: ='APP Медиа'!J54+'APP Перформанс'!J24 -> 615.69874 | ... M5: ='APP Медиа'!N54+'APP Перформанс'!N24 -> 1308.3598 | N5: =SUM(B5:M5) -> 7696.2342 | O5: ='APP Медиа'!P54+'APP Перформанс'!P24 -> 6195.4 | P5: =IFERROR(N5/O5-1,"") -> 0.24224977
A6: Content factory | B6: ='Content factory'!C31 -> 4.266 | C6: ='Content factory'!D31 -> 10.665 | D6: ='Content factory'!E31 -> 14.931 | E6: ='Content factory'!F31 -> 14.931 | F6: ='Content factory'!G31 -> 14.931 | G6: ='Content factory'!H31 -> 14.931 | H6: ='Content factory'!I31 -> 14.931 | I6: ='Content factory'!J31 -> 17.064 | ... M6: ='Content factory'!N31 -> 36.261 | N6: =SUM(B6:M6) -> 213.3 | O6: ='Content factory'!P31 -> 0 | P6: =IFERROR(N6/O6-1,"")
A7: DMP+ Analitycs | B7: =DMP!C20 -> 3.74 | C7: =DMP!D20 -> 9.35 | D7: =DMP!E20 -> 13.09 | E7: =DMP!F20 -> 13.09 | F7: =DMP!G20 -> 13.09 | G7: =DMP!H20 -> 13.09 | H7: =DMP!I20 -> 13.09 | I7: =DMP!J20 -> 14.96 | ... M7: =DMP!N20 -> 31.79 | N7: =SUM(B7:M7) -> 187 | O7: =DMP!O24 -> 102.4 | P7: =IFERROR(N7/O7-1,"") -> 0.82617188
A8: DMP+Online | B8: =DMP!C9 -> 32 | C8: =DMP!D9 -> 80 | D8: =DMP!E9 -> 112 | E8: =DMP!F9 -> 112 | F8: =DMP!G9 -> 112 | G8: =DMP!H9 -> 112 | H8: =DMP!I9 -> 112 | I8: =DMP!J9 -> 128 | ... M8: =DMP!N9 -> 272 | N8: =SUM(B8:M8) -> 1600 | O8: =DMP!O23 -> 987 | P8: =IFERROR(N8/O8-1,"") -> 0.62107396
A9: Instore digital | B9: ='In-store'!C28 -> 80.390907 | C9: ='In-store'!D28 -> 200.98173 | D9: ='In-store'!E28 -> 281.36817 | E9: ='In-store'!F28 -> 281.35478 | F9: ='In-store'!G28 -> 281.36817 | G9: ='In-store'!H28 -> 281.36817 | H9: ='In-store'!I28 -> 281.36817 | I9: ='In-store'!J28 -> 321.5413 | ... M9: ='In-store'!N28 -> 683.32271 | N9: =SUM(B9:M9) -> 4019.4918 | O9: ='In-store'!P28 -> 2446.0892 | P9: =IFERROR(N9/O9-1,"") -> 0.64323186
A10: RMN (Brand budgets call) | B10: =RevSplit!F10 -> 17.004183 | C10: =RevSplit!G10 -> 42.510457 | D10: =RevSplit!H10 -> 59.51464 | E10: =RevSplit!I10 -> 59.51464 | F10: =RevSplit!J10 -> 59.51464 | G10: =RevSplit!K10 -> 59.51464 | H10: =RevSplit!L10 -> 59.51464 | I10: =RevSplit!M10 -> 68.016732 | ... M10: =RevSplit!Q10 -> 144.53555 | N10: =SUM(B10:M10) -> 850.20914 | O10: =RevSplit!S10 -> 592.56 | P10: =IFERROR(N10/O10-1,"") -> 0.43480685
A11: Gross Revenue | B11: =SUM(B5:B10) -> 291.32577 | C11: =SUM(C5:C10) -> 728.3189 | D11: =SUM(D5:D10) -> 1019.6402 | E11: =SUM(E5:E10) -> 1019.6268 | F11: =SUM(F5:F10) -> 1019.6402 | G11: =SUM(G5:G10) -> 1019.6402 | H11: =SUM(H5:H10) -> 1019.6402 | I11: =SUM(I5:I10) -> 1165.2808 | ... M11: =SUM(M5:M10) -> 2476.2691 | N11: =SUM(B11:M11) -> 14566.235 | O11: =SUM(O5:O10) -> 10323.449
A12: Расходы на маркетинг в сети интернет | B12: =Расходы!C26 -> -19.3793 | C12: =Расходы!D26 -> -51.604294 | D12: =Расходы!E26 -> -68.277733 | E12: =Расходы!F26 -> -71.584631 | F12: =Расходы!G26 -> -72.296031 | G12: =Расходы!H26 -> -72.409411 | H12: =Расходы!I26 -> -72.362725 | I12: =Расходы!J26 -> -81.232995 | ... M12: =Расходы!N26 -> -163.80337 | N12: =SUM(B12:M12) -> -1000 | O12: =Расходы!P26 -> -510.54
A13: Вознаграждения креаторам | B13: =Расходы!C27 -> -4.24 | C13: =Расходы!D27 -> -7.42 | D13: =Расходы!E27 -> -14.31 | E13: =Расходы!F27 -> -14.787 | F13: =Расходы!G27 -> -15.105 | G13: =Расходы!H27 -> -15.9 | H13: =Расходы!I27 -> -15.9 | I13: =Расходы!J27 -> -17.013 | ... M13: =Расходы!N27 -> -19.08 | N13: =SUM(B13:M13) -> -176.066 | O13: -15.6
A14: Вознаграждения рекламным агентствам | B14: =Расходы!C28 -> -66.25 | C14: =Расходы!D28 -> -66.25 | D14: =Расходы!E28 -> -66.25 | E14: =Расходы!F28 -> -66.25 | F14: =Расходы!G28 -> -66.25 | G14: =Расходы!H28 -> -66.25 | H14: =Расходы!I28 -> -66.25 | I14: =Расходы!J28 -> -66.25 | ... M14: =Расходы!N28 -> -66.25 | N14: =SUM(B14:M14) -> -795 | O14: =Расходы!P28 -> -354.4
A15: COGS (расходы, привязанные к выручке) | B15: =SUM(B12:B14) -> -89.8693 | C15: =SUM(C12:C14) -> -125.27429 | D15: =SUM(D12:D14) -> -148.83773 | E15: =SUM(E12:E14) -> -152.62163 | F15: =SUM(F12:F14) -> -153.65103 | G15: =SUM(G12:G14) -> -154.55941 | H15: =SUM(H12:H14) -> -154.51273 | I15: =SUM(I12:I14) -> -164.49599 | ... M15: =SUM(M12:M14) -> -249.13337 | N15: =SUM(B15:M15) -> -1971.066 | O15: =SUM(O12:O14) -> -880.54
A16: Net Revenue | B16: =B11+B15 -> 201.45647 | C16: =C11+C15 -> 603.04461 | D16: =D11+D15 -> 870.80248 | E16: =E11+E15 -> 867.00518 | F16: =F11+F15 -> 865.98918 | G16: =G11+G15 -> 865.0808 | H16: =H11+H15 -> 865.12748 | I16: =I11+I15 -> 1000.7848 | ... M16: =M11+M15 -> 2227.1357 | N16: =SUM(B16:M16) -> 12595.169 | O16: =O11+O15 -> 9442.9092
A17: Налоги и взносы, связанные с расходами на оплату труда (ФОТ) | B17: =Расходы!C3 -> -20.502132 | C17: =Расходы!D3 -> -20.887499 | D17: =Расходы!E3 -> -20.996231 | E17: =Расходы!F3 -> -21.347445 | F17: =Расходы!G3 -> -21.745961 | G17: =Расходы!H3 -> -21.199164 | H17: =Расходы!I3 -> -21.729056 | I17: =Расходы!J3 -> -18.508763 | ... M17: =Расходы!N3 -> -23.873296 | N17: =SUM(B17:M17) -> -258.40169 | O17: =Расходы!P3 -> -201.50085
A18: Индексация | B18: =Расходы!C4 -> 0 | C18: =Расходы!D4 -> 0 | D18: =Расходы!E4 -> 0 | E18: =Расходы!F4 -> 0 | F18: =Расходы!G4 -> 0 | G18: =Расходы!H4 -> 0 | H18: =Расходы!I4 -> 0 | I18: =Расходы!J4 -> 0 | ... M18: =Расходы!N4 -> 0 | N18: =SUM(B18:M18) -> 0 | O18: =Расходы!P4 -> 0
A19: Оплата труда - постоянная часть | B19: =Расходы!C5 -> -71.250322 | C19: =Расходы!D5 -> -72.589574 | D19: =Расходы!E5 -> -72.967448 | E19: =Расходы!F5 -> -74.188009 | F19: =Расходы!G5 -> -75.572956 | G19: =Расходы!H5 -> -73.672694 | H19: =Расходы!I5 -> -75.514206 | I19: =Расходы!J5 -> -64.322839 | ... M19: =Расходы!N5 -> -82.966006 | N19: =SUM(B19:M19) -> -898.01411 | O19: =Расходы!P5 -> -700.26866
A20: Оплата труда - премии | B20: =Расходы!C6 -> -2.6895515 | C20: =Расходы!D6 -> -2.7401055 | D20: =Расходы!E6 -> -2.7543694 | E20: =Расходы!F6 -> -2.8004431 | F20: =Расходы!G6 -> -2.852722 | G20: =Расходы!H6 -> -2.780991 | H20: =Расходы!I6 -> -2.8505043 | I20: =Расходы!J6 -> -2.4280534 | ... M20: =Расходы!N6 -> -3.1317942 | N20: =SUM(B20:M20) -> -33.898165 | O20: =Расходы!P6 -> -26.433686
A21: Оплата труда - отпускные | B21: =Расходы!C7 -> -4.6155439 | C21: =Расходы!D7 -> -4.7022997 | D21: =Расходы!E7 -> -4.7267781 | E21: =Расходы!F7 -> -4.8058451 | F21: =Расходы!G7 -> -4.895561 | G21: =Расходы!H7 -> -4.7724634 | H21: =Расходы!I7 -> -4.8917552 | I21: =Расходы!J7 -> -4.1667866 | ... M21: =Расходы!N7 -> -5.3744774 | N21: =SUM(B21:M21) -> -58.172699 | O21: =Расходы!P7 -> -45.362893
A22: Начисление резерва STI 100%, годовой бонус | B22: =Расходы!C8 -> -11.555954 | C22: =Расходы!D8 -> -11.773165 | D22: =Расходы!E8 -> -11.834452 | E22: =Расходы!F8 -> -12.032412 | F22: =Расходы!G8 -> -12.257034 | G22: =Расходы!H8 -> -11.948834 | H22: =Расходы!I8 -> -12.247506 | I22: =Расходы!J8 -> -10.432399 | ... M22: =Расходы!N8 -> -13.456099 | N22: =SUM(B22:M22) -> -145.6472 | O22: =Расходы!P8 -> -113.57524
A23: Начисление резерва STI 100%, квартальные бонусы | B23: =Расходы!C9 -> -3.350543 | C23: =Расходы!D9 -> -3.4135212 | D23: =Расходы!E9 -> -3.4312907 | E23: =Расходы!F9 -> -3.4886876 | F23: =Расходы!G9 -> -3.5538146 | G23: =Расходы!H9 -> -3.4644549 | H23: =Расходы!I9 -> -3.5510519 | I23: =Расходы!J9 -> -3.0247784 | ... M23: =Расходы!N9 -> -3.9014725 | N23: =SUM(B23:M23) -> -42.22907 | O23: =Расходы!P9 -> -32.9301
A24: PEX | B24: =SUM(B17:B23) -> -113.96405 | C24: =SUM(C17:C23) -> -116.10616 | D24: =SUM(D17:D23) -> -116.71057 | E24: =SUM(E17:E23) -> -118.66284 | F24: =SUM(F17:F23) -> -120.87805 | G24: =SUM(G17:G23) -> -117.8386 | H24: =SUM(H17:H23) -> -120.78408 | I24: =SUM(I17:I23) -> -102.88362 | ... M24: =SUM(M17:M23) -> -132.70314 | N24: =SUM(B24:M24) -> -1436.3629 | O24: =SUM(O17:O23) -> -1120.0714
A25: Материальная помощь | B25: =Расходы!C11 -> -0.005 | C25: =Расходы!D11 -> 0 | D25: =Расходы!E11 -> -0.005 | E25: =Расходы!F11 -> -0.005 | F25: =Расходы!G11 -> -0.005 | G25: =Расходы!H11 -> 0 | H25: =Расходы!I11 -> -0.005 | I25: =Расходы!J11 -> 0 | ... M25: =Расходы!N11 -> -0.005 | N25: =SUM(B25:M25) -> -0.04 | O25: =Расходы!P11 -> -0.4
A26: Затраты на корп. мероприятие кроме проезда и проживания | B26: =Расходы!C12 -> -0.375 | C26: =Расходы!D12 -> -0.375 | D26: =Расходы!E12 -> -0.51 | E26: =Расходы!F12 -> -0.375 | F26: =Расходы!G12 -> -0.375 | G26: =Расходы!H12 -> -0.375 | H26: =Расходы!I12 -> -0.51 | I26: =Расходы!J12 -> -0.375 | ... M26: =Расходы!N12 -> -0.375 | N26: =SUM(B26:M26) -> -4.77 | O26: =Расходы!P12 -> -3
A27: ДМС и НС | B27: =Расходы!C13 -> -0.86919813 | C27: =Расходы!D13 -> -0.86919813 | D27: =Расходы!E13 -> -0.86919813 | E27: =Расходы!F13 -> -0.86919813 | F27: =Расходы!G13 -> -0.86919813 | G27: =Расходы!H13 -> -0.86919813 | H27: =Расходы!I13 -> -0.86919813 | I27: =Расходы!J13 -> -0.86919813 | ... M27: =Расходы!N13 -> -0.97250298 | N27: =SUM(B27:M27) -> -10.546904 | O27: =Расходы!P13 -> -6.5
A28: Подбор массовых позиций | B28: =Расходы!C14 -> 0 | C28: =Расходы!D14 -> 0 | D28: =Расходы!E14 -> 0 | E28: =Расходы!F14 -> 0 | F28: =Расходы!G14 -> 0 | G28: =Расходы!H14 -> 0 | H28: =Расходы!I14 -> 0 | I28: =Расходы!J14 -> 0 | ... M28: =Расходы!N14 -> 0 | N28: =SUM(B28:M28) -> 0 | O28: =Расходы!P14 -> -4.9
A29: Подбор офисных позиций | B29: =Расходы!C15 -> -0.037333 | C29: =Расходы!D15 -> -0.037333 | D29: =Расходы!E15 -> -0.037333 | E29: =Расходы!F15 -> -0.37233367 | F29: =Расходы!G15 -> -0.037333 | G29: =Расходы!H15 -> -0.037333 | H29: =Расходы!I15 -> -0.037333 | I29: =Расходы!J15 -> -0.377003 | ... M29: =Расходы!N15 -> -0.037333 | N29: =SUM(B29:M29) -> -1.1226667 | O29: =Расходы!P15 -> 0
A30: Расходы на внешнее обучение | B30: =Расходы!C16 -> 0 | C30: =Расходы!D16 -> 0 | D30: =Расходы!E16 -> -0.51209 | E30: =Расходы!F16 -> -0.51209 | F30: =Расходы!G16 -> -0.51209 | G30: =Расходы!H16 -> -0.51209 | H30: =Расходы!I16 -> -0.51209 | I30: =Расходы!J16 -> -0.51209 | ... M30: =Расходы!N16 -> -0.51209 | N30: =SUM(B30:M30) -> -5.1209 | O30: =Расходы!P16 -> -5.7
A31: Развитие HR бренда | B31: =Расходы!C17 -> 0 | C31: =Расходы!D17 -> -4 | D31: =Расходы!E17 -> 0 | E31: =Расходы!F17 -> -10.25 | F31: =Расходы!G17 -> 0 | G31: =Расходы!H17 -> 0 | H31: =Расходы!I17 -> -6 | I31: =Расходы!J17 -> 0 | ... M31: =Расходы!N17 -> 0 | N31: =SUM(B31:M31) -> -20.25 | O31: =Расходы!P17 -> -14
A32: Карты лояльности (мотивация сотрудников) | B32: =Расходы!C18 -> -0.02799675 | C32: =Расходы!D18 -> -0.02799675 | D32: =Расходы!E18 -> -0.02799675 | E32: =Расходы!F18 -> -0.02799675 | F32: =Расходы!G18 -> -0.02799675 | G32: =Расходы!H18 -> -0.02799675 | H32: =Расходы!I18 -> -0.02799675 | I32: =Расходы!J18 -> -0.02799675 | ... M32: =Расходы!N18 -> -0.02799675 | N32: =SUM(B32:M32) -> -0.335961 | O32: =Расходы!P18 -> 0
A33: Прочие компенсации и льготы | B33: =Расходы!C19 -> -0.041666667 | C33: =Расходы!D19 -> -0.041666667 | D33: =Расходы!E19 -> -0.041666667 | E33: =Расходы!F19 -> -0.041666667 | F33: =Расходы!G19 -> -0.041666667 | G33: =Расходы!H19 -> -0.041666667 | H33: =Расходы!I19 -> -0.041666667 | I33: =Расходы!J19 -> -0.041666667 | ... M33: =Расходы!N19 -> -0.041666667 | N33: =SUM(B33:M33) -> -0.5 | O33: =Расходы!P19 -> -1.2
A34: Резерв на оплату отпусков | B34: =Расходы!C20 -> 0.2 | C34: =Расходы!D20 -> 0.2 | D34: =Расходы!E20 -> 0.2 | E34: =Расходы!F20 -> 0.2 | F34: =Расходы!G20 -> 0.2 | G34: =Расходы!H20 -> 0.2 | H34: =Расходы!I20 -> 0.2 | I34: =Расходы!J20 -> 0.2 | ... M34: =Расходы!N20 -> 0.2 | N34: =SUM(B34:M34) -> 2.4 | O34: =Расходы!P20 -> 3
A35: Other PEX | B35: =SUM(B25:B34) -> -1.1561945 | C35: =SUM(C25:C34) -> -5.1511945 | D35: =SUM(D25:D34) -> -1.8032845 | E35: =SUM(E25:E34) -> -12.253285 | F35: =SUM(F25:F34) -> -1.6682845 | G35: =SUM(G25:G34) -> -1.6632845 | H35: =SUM(H25:H34) -> -7.8032845 | I35: =SUM(I25:I34) -> -2.0029545 | ... M35: =SUM(M25:M34) -> -1.7715894 | N35: =SUM(B35:M35) -> -40.286432 | O35: =SUM(O25:O34) -> -32.7
A36: PR/GR | B36: =Расходы!C22 -> -0.675 | C36: =Расходы!D22 -> -3.525 | D36: =Расходы!E22 -> -4.25 | E36: =Расходы!F22 -> -2.675 | F36: =Расходы!G22 -> -0.875 | G36: =Расходы!H22 -> -1.9 | H36: =Расходы!I22 -> -4.675 | I36: =Расходы!J22 -> -2.025 | ... M36: =Расходы!N22 -> -1.4 | N36: =SUM(B36:M36) -> -33.3 | O36: =Расходы!P22 -> -23.25
A37: Организация бизнес-мероприятий для партнеров | B37: =Расходы!C23 -> 0 | C37: =Расходы!D23 -> -1.5 | D37: =Расходы!E23 -> 0 | E37: =Расходы!F23 -> 0 | F37: =Расходы!G23 -> 0 | G37: =Расходы!H23 -> -0.15 | H37: =Расходы!I23 -> 0 | I37: =Расходы!J23 -> 0 | ... M37: =Расходы!N23 -> 0 | N37: =SUM(B37:M37) -> -1.8 | O37: =Расходы!P23 -> -3.5
A38: Маркетинговые исследования | B38: =Расходы!C24 -> -1.1260256 | C38: =Расходы!D24 -> -1.1260256 | D38: =Расходы!E24 -> -1.1260256 | E38: =Расходы!F24 -> -1.1260256 | F38: =Расходы!G24 -> -1.1260256 | G38: =Расходы!H24 -> -1.1260256 | H38: =Расходы!I24 -> -1.4670104 | I38: =Расходы!J24 -> -1.4670104 | ... M38: =Расходы!N24 -> -1.4670104 | N38: =SUM(B38:M38) -> -15.558216 | O38: =Расходы!P24 -> -8.3
A39: Маркетинг ВГО (не поставщики) | B39: =Расходы!C25 -> -4.1666667 | C39: =Расходы!D25 -> -4.1666667 | D39: =Расходы!E25 -> -4.1666667 | E39: =Расходы!F25 -> -4.1666667 | F39: =Расходы!G25 -> -4.1666667 | G39: =Расходы!H25 -> -4.1666667 | H39: =Расходы!I25 -> -4.1666667 | I39: =Расходы!J25 -> -4.1666667 | ... M39: =Расходы!N25 -> -4.1666667 | N39: =SUM(B39:M39) -> -50 | O39: =Расходы!P25 -> -20.2
A40: Marketing | B40: =SUM(B36:B39) -> -5.9676923 | C40: =SUM(C36:C39) -> -10.317692 | D40: =SUM(D36:D39) -> -9.5426923 | E40: =SUM(E36:E39) -> -7.9676923 | F40: =SUM(F36:F39) -> -6.1676923 | G40: =SUM(G36:G39) -> -7.3426923 | H40: =SUM(H36:H39) -> -10.308677 | I40: =SUM(I36:I39) -> -7.6586771 | ... M40: =SUM(M36:M39) -> -7.0336771 | N40: =SUM(B40:M40) -> -100.65822 | O40: =SUM(O36:O39) -> -55.25
A41: Техподдержка и сопровождение программного обеспечения | B41: =Расходы!C30 -> -6.4490727 | C41: =Расходы!D30 -> -6.4490727 | D41: =Расходы!E30 -> -6.8490727 | E41: =Расходы!F30 -> -6.6490727 | F41: =Расходы!G30 -> -7.1490727 | G41: =Расходы!H30 -> -7.0995797 | H41: =Расходы!I30 -> -7.0420068 | I41: =Расходы!J30 -> -7.309943 | ... M41: =Расходы!N30 -> -9.4274407 | N41: =SUM(B41:M41) -> -92.100557 | O41: =Расходы!P30 -> -58.6
...

Sheet P&L 2027_Formats
A1: P&L AdTech 2027 - BOTTOM-UP Formats | Q1: Описание: bottom-up P&L AdTech 2027 по месяцам, млн ₽ без НДС. Логика: выручка трансформированная из направлений в форматы - лист «RevSplit»; расходы - из листа «Расходы»
A2: Млн руб. без НДС.
A4: Статья | B4: янв | C4: фев | D4: мар | E4: апр | F4: май | G4: июн | H4: июл | I4: авг | J4: сен | K4: окт | L4: ноя | M4: дек | N4: 2027 | O4: 2026
A5: E-commerce | B5: =RevSplit!X5 -> 153.92468 | C5: =RevSplit!Y5 -> 384.81171 | D5: =RevSplit!Z5 -> 538.73639 | E5: =RevSplit!AA5 -> 538.73639 | F5: =RevSplit!AB5 -> 538.73639 | G5: =RevSplit!AC5 -> 538.73639 | H5: =RevSplit!AD5 -> 538.73639 | I5: =RevSplit!AE5 -> 615.69874 | ... M5: =RevSplit!AI5 -> 1308.3598 | N5: =SUM(B5:M5) -> 7696.2342 | O5: =RevSplit!AK5 -> 6195.4 | P5: =IFERROR(N5/O5-1,"") -> 0.24224977
A6: ММ | B6: =RevSplit!X6 -> 61.119537 | C6: =RevSplit!Y6 -> 152.80189 | D6: =RevSplit!Z6 -> 213.91838 | E6: =RevSplit!AA6 -> 213.90924 | F6: =RevSplit!AB6 -> 213.91838 | G6: =RevSplit!AC6 -> 213.91838 | H6: =RevSplit!AD6 -> 213.91838 | I6: =RevSplit!AE6 -> 244.46291 | ... M6: =RevSplit!AI6 -> 519.51607 | N6: =SUM(B6:M6) -> 3055.9403 | O6: =RevSplit!AK6 -> 1862.3131 | P6: =IFERROR(N6/O6-1,"") -> 0.64093801
A7: МК | B7: =RevSplit!X7 -> 32.795963 | C7: =RevSplit!Y7 -> 81.990345 | D7: =RevSplit!Z7 -> 114.78587 | E7: =RevSplit!AA7 -> 114.78456 | F7: =RevSplit!AB7 -> 114.78587 | G7: =RevSplit!AC7 -> 114.78587 | H7: =RevSplit!AD7 -> 114.78587 | I7: =RevSplit!AE7 -> 131.18167 | ... M7: =RevSplit!AI7 -> 278.76569 | N7: =SUM(B7:M7) -> 1639.7929 | O7: =RevSplit!AK7 -> 1008.2743 | P7: =IFERROR(N7/O7-1,"") -> 0.6263362
A8: МЭ | B8: =RevSplit!X8 -> 11.157443 | C8: =RevSplit!Y8 -> 27.894193 | D8: =RevSplit!Z8 -> 39.051051 | E8: =RevSplit!AA8 -> 39.049293 | F8: =RevSplit!AB8 -> 39.051051 | G8: =RevSplit!AC8 -> 39.051051 | H8: =RevSplit!AD8 -> 39.051051 | I8: =RevSplit!AE8 -> 44.626843 | ... M8: =RevSplit!AI8 -> 94.838266 | N8: =SUM(B8:M8) -> 557.86512 | O8: =RevSplit!AK8 -> 339.74806 | P8: =IFERROR(N8/O8-1,"") -> 0.64199647
A9: МС | B9: =RevSplit!X9 -> 4.9806379 | C9: =RevSplit!Y9 -> 12.45186 | D9: =RevSplit!Z9 -> 17.432233 | E9: =RevSplit!AA9 -> 17.431437 | F9: =RevSplit!AB9 -> 17.432233 | G9: =RevSplit!AC9 -> 17.432233 | H9: =RevSplit!AD9 -> 17.432233 | I9: =RevSplit!AE9 -> 19.921226 | ... M9: =RevSplit!AI9 -> 42.335422 | N9: =SUM(B9:M9) -> 249.02871 | O9: =RevSplit!AK9 -> 151.63503 | P9: =IFERROR(N9/O9-1,"") -> 0.64229009
A10: МС Лайт | B10: =RevSplit!X10 -> 2.3373256 | C10: =RevSplit!Y10 -> 5.8434438 | D10: =RevSplit!Z10 -> 8.1806395 | E10: =RevSplit!AA10 -> 8.1802499 | F10: =RevSplit!AB10 -> 8.1806395 | G10: =RevSplit!AC10 -> 8.1806395 | H10: =RevSplit!AD10 -> 8.1806395 | I10: =RevSplit!AE10 -> 9.348653 | ... M10: =RevSplit!AI10 -> 19.867267 | N10: =SUM(B10:M10) -> 116.86472 | O10: =RevSplit!AK10 -> 71.118826 | P10: =IFERROR(N10/O10-1,"") -> 0.64323186
A11: Без формата | B11: =RevSplit!X11 -> 25.010183 | C11: =RevSplit!Y11 -> 62.525457 | D11: =RevSplit!Z11 -> 87.53564 | E11: =RevSplit!AA11 -> 87.53564 | F11: =RevSplit!AB11 -> 87.53564 | G11: =RevSplit!AC11 -> 87.53564 | H11: =RevSplit!AD11 -> 87.53564 | I11: =RevSplit!AE11 -> 100.04073 | ... M11: =RevSplit!AI11 -> 212.58655 | N11: =SUM(B11:M11) -> 1250.5091 | O11: =RevSplit!AK11 -> 694.96 | P11: =IFERROR(N11/O11-1,"") -> 0.7993973
A12: Gross Revenue | B12: =SUM(B5:B11) -> 291.32577 | C12: =SUM(C5:C11) -> 728.3189 | D12: =SUM(D5:D11) -> 1019.6402 | E12: =SUM(E5:E11) -> 1019.6268 | F12: =SUM(F5:F11) -> 1019.6402 | G12: =SUM(G5:G11) -> 1019.6402 | H12: =SUM(H5:H11) -> 1019.6402 | I12: =SUM(I5:I11) -> 1165.2808 | ... M12: =SUM(M5:M11) -> 2476.2691 | N12: =SUM(B12:M12) -> 14566.235 | O12: =SUM(O5:O11) -> 10323.449
A13: Расходы на маркетинг в сети интернет | B13: =Расходы!C26 -> -19.3793 | C13: =Расходы!D26 -> -51.604294 | D13: =Расходы!E26 -> -68.277733 | E13: =Расходы!F26 -> -71.584631 | F13: =Расходы!G26 -> -72.296031 | G13: =Расходы!H26 -> -72.409411 | H13: =Расходы!I26 -> -72.362725 | I13: =Расходы!J26 -> -81.232995 | ... M13: =Расходы!N26 -> -163.80337 | N13: =SUM(B13:M13) -> -1000 | O13: =Расходы!P26 -> -510.54
A14: Вознаграждения креаторам | B14: =Расходы!C27 -> -4.24 | C14: =Расходы!D27 -> -7.42 | D14: =Расходы!E27 -> -14.31 | E14: =Расходы!F27 -> -14.787 | F14: =Расходы!G27 -> -15.105 | G14: =Расходы!H27 -> -15.9 | H14: =Расходы!I27 -> -15.9 | I14: =Расходы!J27 -> -17.013 | ... M14: =Расходы!N27 -> -19.08 | N14: =SUM(B14:M14) -> -176.066 | O14: -15.6
A15: Вознаграждения рекламным агентствам | B15: =Расходы!C28 -> -66.25 | C15: =Расходы!D28 -> -66.25 | D15: =Расходы!E28 -> -66.25 | E15: =Расходы!F28 -> -66.25 | F15: =Расходы!G28 -> -66.25 | G15: =Расходы!H28 -> -66.25 | H15: =Расходы!I28 -> -66.25 | I15: =Расходы!J28 -> -66.25 | ... M15: =Расходы!N28 -> -66.25 | N15: =SUM(B15:M15) -> -795 | O15: =Расходы!P28 -> -354.4
A16: COGS (расходы, привязанные к выручке) | B16: =SUM(B13:B15) -> -89.8693 | C16: =SUM(C13:C15) -> -125.27429 | D16: =SUM(D13:D15) -> -148.83773 | E16: =SUM(E13:E15) -> -152.62163 | F16: =SUM(F13:F15) -> -153.65103 | G16: =SUM(G13:G15) -> -154.55941 | H16: =SUM(H13:H15) -> -154.51273 | I16: =SUM(I13:I15) -> -164.49599 | ... M16: =SUM(M13:M15) -> -249.13337 | N16: =SUM(B16:M16) -> -1971.066 | O16: =SUM(O13:O15) -> -880.54
A17: Net Revenue | B17: =B12+B16 -> 201.45647 | C17: =C12+C16 -> 603.04461 | D17: =D12+D16 -> 870.80248 | E17: =E12+E16 -> 867.00518 | F17: =F12+F16 -> 865.98918 | G17: =G12+G16 -> 865.0808 | H17: =H12+H16 -> 865.12748 | I17: =I12+I16 -> 1000.7848 | ... M17: =M12+M16 -> 2227.1357 | N17: =SUM(B17:M17) -> 12595.169 | O17: =O12+O16 -> 9442.9092
A18: Налоги и взносы, связанные с расходами на оплату труда (ФОТ) | B18: =Расходы!C3 -> -20.502132 | C18: =Расходы!D3 -> -20.887499 | D18: =Расходы!E3 -> -20.996231 | E18: =Расходы!F3 -> -21.347445 | F18: =Расходы!G3 -> -21.745961 | G18: =Расходы!H3 -> -21.199164 | H18: =Расходы!I3 -> -21.729056 | I18: =Расходы!J3 -> -18.508763 | ... M18: =Расходы!N3 -> -23.873296 | N18: =SUM(B18:M18) -> -258.40169 | O18: =Расходы!P3 -> -201.50085
A19: Индексация | B19: =Расходы!C4 -> 0 | C19: =Расходы!D4 -> 0 | D19: =Расходы!E4 -> 0 | E19: =Расходы!F4 -> 0 | F19: =Расходы!G4 -> 0 | G19: =Расходы!H4 -> 0 | H19: =Расходы!I4 -> 0 | I19: =Расходы!J4 -> 0 | ... M19: =Расходы!N4 -> 0 | N19: =SUM(B19:M19) -> 0 | O19: =Расходы!P4 -> 0
A20: Оплата труда - постоянная часть | B20: =Расходы!C5 -> -71.250322 | C20: =Расходы!D5 -> -72.589574 | D20: =Расходы!E5 -> -72.967448 | E20: =Расходы!F5 -> -74.188009 | F20: =Расходы!G5 -> -75.572956 | G20: =Расходы!H5 -> -73.672694 | H20: =Расходы!I5 -> -75.514206 | I20: =Расходы!J5 -> -64.322839 | ... M20: =Расходы!N5 -> -82.966006 | N20: =SUM(B20:M20) -> -898.01411 | O20: =Расходы!P5 -> -700.26866
A21: Оплата труда - премии | B21: =Расходы!C6 -> -2.6895515 | C21: =Расходы!D6 -> -2.7401055 | D21: =Расходы!E6 -> -2.7543694 | E21: =Расходы!F6 -> -2.8004431 | F21: =Расходы!G6 -> -2.852722 | G21: =Расходы!H6 -> -2.780991 | H21: =Расходы!I6 -> -2.8505043 | I21: =Расходы!J6 -> -2.4280534 | ... M21: =Расходы!N6 -> -3.1317942 | N21: =SUM(B21:M21) -> -33.898165 | O21: =Расходы!P6 -> -26.433686
A22: Оплата труда - отпускные | B22: =Расходы!C7 -> -4.6155439 | C22: =Расходы!D7 -> -4.7022997 | D22: =Расходы!E7 -> -4.7267781 | E22: =Расходы!F7 -> -4.8058451 | F22: =Расходы!G7 -> -4.895561 | G22: =Расходы!H7 -> -4.7724634 | H22: =Расходы!I7 -> -4.8917552 | I22: =Расходы!J7 -> -4.1667866 | ... M22: =Расходы!N7 -> -5.3744774 | N22: =SUM(B22:M22) -> -58.172699 | O22: =Расходы!P7 -> -45.362893
A23: Начисление резерва STI 100%, годовой бонус | B23: =Расходы!C8 -> -11.555954 | C23: =Расходы!D8 -> -11.773165 | D23: =Расходы!E8 -> -11.834452 | E23: =Расходы!F8 -> -12.032412 | F23: =Расходы!G8 -> -12.257034 | G23: =Расходы!H8 -> -11.948834 | H23: =Расходы!I8 -> -12.247506 | I23: =Расходы!J8 -> -10.432399 | ... M23: =Расходы!N8 -> -13.456099 | N23: =SUM(B23:M23) -> -145.6472 | O23: =Расходы!P8 -> -113.57524
A24: Начисление резерва STI 100%, квартальные бонусы | B24: =Расходы!C9 -> -3.350543 | C24: =Расходы!D9 -> -3.4135212 | D24: =Расходы!E9 -> -3.4312907 | E24: =Расходы!F9 -> -3.4886876 | F24: =Расходы!G9 -> -3.5538146 | G24: =Расходы!H9 -> -3.4644549 | H24: =Расходы!I9 -> -3.5510519 | I24: =Расходы!J9 -> -3.0247784 | ... M24: =Расходы!N9 -> -3.9014725 | N24: =SUM(B24:M24) -> -42.22907 | O24: =Расходы!P9 -> -32.9301
A25: PEX | B25: =SUM(B18:B24) -> -113.96405 | C25: =SUM(C18:C24) -> -116.10616 | D25: =SUM(D18:D24) -> -116.71057 | E25: =SUM(E18:E24) -> -118.66284 | F25: =SUM(F18:F24) -> -120.87805 | G25: =SUM(G18:G24) -> -117.8386 | H25: =SUM(H18:H24) -> -120.78408 | I25: =SUM(I18:I24) -> -102.88362 | ... M25: =SUM(M18:M24) -> -132.70314 | N25: =SUM(B25:M25) -> -1436.3629 | O25: =SUM(O18:O24) -> -1120.0714
A26: Материальная помощь | B26: =Расходы!C11 -> -0.005 | C26: =Расходы!D11 -> 0 | D26: =Расходы!E11 -> -0.005 | E26: =Расходы!F11 -> -0.005 | F26: =Расходы!G11 -> -0.005 | G26: =Расходы!H11 -> 0 | H26: =Расходы!I11 -> -0.005 | I26: =Расходы!J11 -> 0 | ... M26: =Расходы!N11 -> -0.005 | N26: =SUM(B26:M26) -> -0.04 | O26: =Расходы!P11 -> -0.4
A27: Затраты на корп. мероприятие кроме проезда и проживания | B27: =Расходы!C12 -> -0.375 | C27: =Расходы!D12 -> -0.375 | D27: =Расходы!E12 -> -0.51 | E27: =Расходы!F12 -> -0.375 | F27: =Расходы!G12 -> -0.375 | G27: =Расходы!H12 -> -0.375 | H27: =Расходы!I12 -> -0.51 | I27: =Расходы!J12 -> -0.375 | ... M27: =Расходы!N12 -> -0.375 | N27: =SUM(B27:M27) -> -4.77 | O27: =Расходы!P12 -> -3
A28: ДМС и НС | B28: =Расходы!C13 -> -0.86919813 | C28: =Расходы!D13 -> -0.86919813 | D28: =Расходы!E13 -> -0.86919813 | E28: =Расходы!F13 -> -0.86919813 | F28: =Расходы!G13 -> -0.86919813 | G28: =Расходы!H13 -> -0.86919813 | H28: =Расходы!I13 -> -0.86919813 | I28: =Расходы!J13 -> -0.86919813 | ... M28: =Расходы!N13 -> -0.97250298 | N28: =SUM(B28:M28) -> -10.546904 | O28: =Расходы!P13 -> -6.5
A29: Подбор массовых позиций | B29: =Расходы!C14 -> 0 | C29: =Расходы!D14 -> 0 | D29: =Расходы!E14 -> 0 | E29: =Расходы!F14 -> 0 | F29: =Расходы!G14 -> 0 | G29: =Расходы!H14 -> 0 | H29: =Расходы!I14 -> 0 | I29: =Расходы!J14 -> 0 | ... M29: =Расходы!N14 -> 0 | N29: =SUM(B29:M29) -> 0 | O29: =Расходы!P14 -> -4.9
A30: Подбор офисных позиций | B30: =Расходы!C15 -> -0.037333 | C30: =Расходы!D15 -> -0.037333 | D30: =Расходы!E15 -> -0.037333 | E30: =Расходы!F15 -> -0.37233367 | F30: =Расходы!G15 -> -0.037333 | G30: =Расходы!H15 -> -0.037333 | H30: =Расходы!I15 -> -0.037333 | I30: =Расходы!J15 -> -0.377003 | ... M30: =Расходы!N15 -> -0.037333 | N30: =SUM(B30:M30) -> -1.1226667 | O30: =Расходы!P15 -> 0
A31: Расходы на внешнее обучение | B31: =Расходы!C16 -> 0 | C31: =Расходы!D16 -> 0 | D31: =Расходы!E16 -> -0.51209 | E31: =Расходы!F16 -> -0.51209 | F31: =Расходы!G16 -> -0.51209 | G31: =Расходы!H16 -> -0.51209 | H31: =Расходы!I16 -> -0.51209 | I31: =Расходы!J16 -> -0.51209 | ... M31: =Расходы!N16 -> -0.51209 | N31: =SUM(B31:M31) -> -5.1209 | O31: =Расходы!P16 -> -5.7
A32: Развитие HR бренда | B32: =Расходы!C17 -> 0 | C32: =Расходы!D17 -> -4 | D32: =Расходы!E17 -> 0 | E32: =Расходы!F17 -> -10.25 | F32: =Расходы!G17 -> 0 | G32: =Расходы!H17 -> 0 | H32: =Расходы!I17 -> -6 | I32: =Расходы!J17 -> 0 | ... M32: =Расходы!N17 -> 0 | N32: =SUM(B32:M32) -> -20.25 | O32: =Расходы!P17 -> -14
A33: Карты лояльности (мотивация сотрудников) | B33: =Расходы!C18 -> -0.02799675 | C33: =Расходы!D18 -> -0.02799675 | D33: =Расходы!E18 -> -0.02799675 | E33: =Расходы!F18 -> -0.02799675 | F33: =Расходы!G18 -> -0.02799675 | G33: =Расходы!H18 -> -0.02799675 | H33: =Расходы!I18 -> -0.02799675 | I33: =Расходы!J18 -> -0.02799675 | ... M33: =Расходы!N18 -> -0.02799675 | N33: =SUM(B33:M33) -> -0.335961 | O33: =Расходы!P18 -> 0
A34: Прочие компенсации и льготы | B34: =Расходы!C19 -> -0.041666667 | C34: =Расходы!D19 -> -0.041666667 | D34: =Расходы!E19 -> -0.041666667 | E34: =Расходы!F19 -> -0.041666667 | F34: =Расходы!G19 -> -0.041666667 | G34: =Расходы!H19 -> -0.041666667 | H34: =Расходы!I19 -> -0.041666667 | I34: =Расходы!J19 -> -0.041666667 | ... M34: =Расходы!N19 -> -0.041666667 | N34: =SUM(B34:M34) -> -0.5 | O34: =Расходы!P19 -> -1.2
A35: Резерв на оплату отпусков | B35: =Расходы!C20 -> 0.2 | C35: =Расходы!D20 -> 0.2 | D35: =Расходы!E20 -> 0.2 | E35: =Расходы!F20 -> 0.2 | F35: =Расходы!G20 -> 0.2 | G35: =Расходы!H20 -> 0.2 | H35: =Расходы!I20 -> 0.2 | I35: =Расходы!J20 -> 0.2 | ... M35: =Расходы!N20 -> 0.2 | N35: =SUM(B35:M35) -> 2.4 | O35: =Расходы!P20 -> 3
A36: Other PEX | B36: =SUM(B26:B35) -> -1.1561945 | C36: =SUM(C26:C35) -> -5.1511945 | D36: =SUM(D26:D35) -> -1.8032845 | E36: =SUM(E26:E35) -> -12.253285 | F36: =SUM(F26:F35) -> -1.6682845 | G36: =SUM(G26:G35) -> -1.6632845 | H36: =SUM(H26:H35) -> -7.8032845 | I36: =SUM(I26:I35) -> -2.0029545 | ... M36: =SUM(M26:M35) -> -1.7715894 | N36: =SUM(B36:M36) -> -40.286432 | O36: =SUM(O26:O35) -> -32.7
A37: PR/GR | B37: =Расходы!C22 -> -0.675 | C37: =Расходы!D22 -> -3.525 | D37: =Расходы!E22 -> -4.25 | E37: =Расходы!F22 -> -2.675 | F37: =Расходы!G22 -> -0.875 | G37: =Расходы!H22 -> -1.9 | H37: =Расходы!I22 -> -4.675 | I37: =Расходы!J22 -> -2.025 | ... M37: =Расходы!N22 -> -1.4 | N37: =SUM(B37:M37) -> -33.3 | O37: =Расходы!P22 -> -23.25
