Workbook

Sheet Сплит доходов
B1: Сплит доходов AdTech, 9 мес. 2026 г.
A2: 1. Доходы, отражённые в корпоративном P&L AdTech
A3: млн руб. без НДС. Источник — файл «Доходы AdTech_9м2026»: БиП и 1С — лист «PL AdTech», поставщики М+ — свод УО (инвентарь М+). Строки 7–17 — БиП по статьям за вычетом поставщиков М+ (стр. 19–27). Наименования статей — как в БиП.
B4: Статья | C4: янв | D4: фев | E4: мар | F4: апр | G4: май | H4: июн | I4: июл | J4: авг | K4: сен | L4: 9 мес. | M4: Куда идёт | N4: Комментарий
B5: Итого доходы в корпоративном P&L AdTech | C5: =C6+C18+C28 -> 252.56825 | D5: =D6+D18+D28 -> 448.64008 | E5: =E6+E18+E28 -> 449.85984 | F5: =F6+F18+F28 -> 539.91197 | G5: =G6+G18+G28 -> 778.28413 | H5: =H6+H18+H28 -> 1159.0499 | I5: =I6+I18+I28 -> 969.28172 | J5: =J6+J18+J28 -> 920.74109 | K5: =K6+K18+K28 -> 1110.4758 | L5: =SUM(C5:K5) -> 6628.8128 | M5: (3) Корпоративный P&L AdTech
B6: Направления AdTech (без поставщиков М+) | C6: =SUM(C7:C17) -> 248.72394 | D6: =SUM(D7:D17) -> 444.64632 | E6: =SUM(E7:E17) -> 446.77496 | F6: =SUM(F7:F17) -> 427.07865 | G6: =SUM(G7:G17) -> 659.46378 | H6: =SUM(H7:H17) -> 971.93593 | I6: =SUM(I7:I17) -> 690.84948 | J6: =SUM(J7:J17) -> 720.09745 | K6: =SUM(K7:K17) -> 749.55034 | L6: =SUM(C6:K6) -> 5359.1209 | M6: (1) Коммерция (Д. Ардаширов); (2) мастер-файл: BiP (Rev) | N6: Стр. 7–17
B7: AdTech_Лояльность М-плюс (CVM, CRM)_ | C7: 0 | D7: 0 | E7: 0 | F7: 0 | G7: 0 | H7: 0 | I7: 0 | J7: 0 | K7: -2.8e-07 | L7: =SUM(C7:K7) -> -2.8e-07
B8: AdTech_Реклама и продвижение_ | C8: 0 | D8: 0 | E8: 0 | F8: 0 | G8: 0 | H8: 0 | I8: 0 | J8: 0 | K8: 3.68e-07 | L8: =SUM(C8:K8) -> 3.68e-07
B9: AdTech_Лояльность М-плюс (CVM, CRM) | C9: 0 | D9: 0 | E9: 0 | F9: 0 | G9: 0 | H9: 0 | I9: 0 | J9: 0 | K9: 1.09007e-06 | L9: =SUM(C9:K9) -> 1.09007e-06
B10: AdTech_Лояльность М-плюс (CVM, CRM) (РА) | C10: 0 | D10: 0 | E10: 0 | F10: 0 | G10: 0 | H10: 0 | I10: 0 | J10: 0 | K10: -1.1e-06 | L10: =SUM(C10:K10) -> -1.1e-06
B11: AdTech_Прочее (РА) | C11: 0 | D11: 0 | E11: 0 | F11: 0 | G11: 0 | H11: 0 | I11: 0.969532 | J11: 16.921116 | K11: 0 | L11: =SUM(C11:K11) -> 17.890648
B12: AdTech_Реклама и продвижение | C12: 59.175726 | D12: 81.570854 | E12: 30.571166 | F12: 60.296807 | G12: 120.76313 | H12: 215.16939 | I12: 82.91801 | J12: 148.80033 | K12: 155.72437 | L12: =SUM(C12:K12) -> 954.98979
B13: AdTech_Реклама и продвижение (РА) | C13: 39.08459 | D13: 76.759578 | E13: 115.98453 | F13: 36.061969 | G13: 175.44924 | H13: 197.86243 | I13: 213.9033 | J13: 185.1729 | K13: 141.15943 | L13: =SUM(C13:K13) -> 1181.438
A14: E-com | B14: E-Commerce_Adtech | C14: 57.901587 | D14: 166.44883 | E14: 194.04925 | F14: 162.74096 | G14: 233.21138 | H14: 355.18202 | I14: 227.14484 | J14: 262.20676 | K14: 312.51298 | L14: =SUM(C14:K14) -> 1971.3986
A15: E-com | B15: E-Commerce_Adtech (РА) | C15: 51.025387 | D15: 102.24909 | E15: 118.87439 | F15: 151.75137 | G15: 182.76472 | H15: 192.51075 | I15: 169.25908 | J15: 106.51169 | K15: 143.70567 | L15: =SUM(C15:K15) -> 1218.6522
A16: E-com | B16: E-Commerce_Реклама и продвижение (условное) | C16: 27.606106 | D16: 6.626706 | E16: -11.711405 | F16: 16.227535 | G16: -52.008751 | H16: 10.717533 | I16: -3.345288 | J16: 0.48465 | K16: 1.1491465 | L16: =SUM(C16:K16) -> -4.2537675
A17: E-com | B17: E-Commerce_Реклама и продвижение (условное) (РА) | C17: 13.930547 | D17: 10.991265 | E17: -0.992964 | F17: 0 | G17: -0.715955 | H17: 0.4938 | I17: 0 | J17: 0 | K17: -4.701255 | L17: =SUM(C17:K17) -> 19.005438
B18: Поставщики М+ | C18: =SUM(C19:C27) -> 0 | D18: =SUM(D19:D27) -> 0 | E18: =SUM(E19:E27) -> 0 | F18: =SUM(F19:F27) -> 95.675717 | G18: =SUM(G19:G27) -> 103.75446 | H18: =SUM(H19:H27) -> 173.27108 | I18: =SUM(I19:I27) -> 235.51306 | J18: =SUM(J19:J27) -> 136.07702 | K18: =SUM(K19:K27) -> 251.36284 | L18: =SUM(C18:K18) -> 995.65418 | M18: (2) Мастер-файл: BiP (Rev) | N18: Учёт с апреля 2026 г.
B19: AdTech_Лояльность М-плюс (CVM, CRM) | K19: 19.701068 | L19: =SUM(C19:K19) -> 19.701068
B20: AdTech_Лояльность М-плюс (CVM, CRM) (РА) | J20: 10.485003 | K20: 33.194554 | L20: =SUM(C20:K20) -> 43.679557
B21: AdTech_Лояльность М-плюс (CVM, CRM)_ | K21: 0.83000328 | L21: =SUM(C21:K21) -> 0.83000328
B22: AdTech_Реклама и продвижение | F22: 58.198698 | G22: 20.970046 | H22: 58.676853 | I22: 97.375914 | J22: 44.554412 | K22: 43.949211 | L22: =SUM(C22:K22) -> 323.72513
B23: AdTech_Реклама и продвижение (РА) | F23: 37.477018 | G23: 82.784414 | H23: 114.59423 | I23: 68.463171 | J23: 59.963172 | K23: 102.07269 | L23: =SUM(C23:K23) -> 465.35469
B24: AdTech_Реклама и продвижение_ | K24: 4.1907326 | L24: =SUM(C24:K24) -> 4.1907326
A25: E-com | B25: E-Commerce_Adtech | I25: 47.572788 | J25: 9.4880477 | K25: 43.847372 | L25: =SUM(C25:K25) -> 100.90821
A26: E-com | B26: E-Commerce_Adtech (РА) | I26: 22.101188 | J26: 11.586387 | K26: 3.0770676 | L26: =SUM(C26:K26) -> 36.764643
A27: E-com | B27: E-Commerce_Реклама и продвижение (условное) | K27: 0.50014046 | L27: =SUM(C27:K27) -> 0.50014046
B28: 1С | C28: 3.844306 | D28: 3.993751 | E28: 3.084882 | F28: 17.157609 | G28: 15.065895 | H28: 13.842933 | I28: 42.919176 | J28: 64.566611 | K28: 109.56258 | L28: =SUM(C28:K28) -> 274.03774 | M28: (3) Корпоративный P&L AdTech; (4) мастер-файл: финальная выручка | N28: В т.ч. ФинТех, М+ (не поставщики), Яндекс (Digital Instore)
A30: 2. Доходы AdTech, не отражённые в корпоративном P&L (сделки на РН других направлений)
A31: млн руб. без НДС. Источник — лист «Доходы, не РН AdTech» файла «Доходы AdTech_9м2026»: сделки, закрытые на РН других направлений, по данным ДО AdTech.
B32: Статья | C32: янв | D32: фев | E32: мар | F32: апр | G32: май | H32: июн | I32: июл | J32: авг | K32: сен | L32: 9 мес. | M32: Куда идёт | N32: Комментарий
B33: Итого доходы на РН других направлений | C33: =SUM(C34:C43) -> 16.798249 | D33: =SUM(D34:D43) -> 3.7234038 | E33: =SUM(E34:E43) -> 102.42666 | F33: =SUM(F34:F43) -> 24.25589 | G33: =SUM(G34:G43) -> 19.900389 | H33: =SUM(H34:H43) -> 223.58594 | I33: =SUM(I34:I43) -> 275.55831 | J33: =SUM(J34:J43) -> 199.51817 | K33: =SUM(K34:K43) -> 401.96369 | L33: =SUM(C33:K33) -> 1267.7307 | M33: (1) Коммерция (Д. Ардаширов)
B34: Digital Instore | C34: 3.2982485 | D34: 0.063375 | G34: 11.210375 | H34: 58.946704 | I34: 108.52295 | J34: 77.217007 | K34: 233.54183 | L34: =SUM(C34:K34) -> 492.80048
B35: Online+DMP | C35: 13.5 | H35: 124.88541 | I35: 57.218154 | J35: 86.41895 | K35: 95.316528 | L35: =SUM(C35:K35) -> 377.33904
B36: М+ | E36: 102.42666 | F36: 24.25589 | G36: 5.0878533 | H36: 37.761756 | I36: 96.54571 | J36: 27.918098 | K36: 39.088497 | L36: =SUM(C36:K36) -> 333.08446
B37: E-comm | G37: -0.1018417 | H37: 0.74206746 | I37: 9.9012368 | J37: 0.29411928 | K37: 34.319024 | L37: =SUM(C37:K37) -> 45.154606
B38: Пакеты | H38: 1.6 | J38: 7.67 | K38: -2.591564 | L38: =SUM(C38:K38) -> 6.678436
B39: POSM | D39: 3.6600288 | G39: 3.7040025 | H39: -0.85 | L39: =SUM(C39:K39) -> 6.5140313
B40: ММ | I40: 3.370256 | L40: =SUM(C40:K40) -> 3.370256
B41: Реклама на транспорте | K41: 2.4000018 | L41: =SUM(C41:K41) -> 2.4000018
...

Sheet Куда идёт выручка
B1: Куда идёт выручка AdTech: компоненты и отчёты, 9 мес. 2026 г.
B2: млн руб. без НДС. Значения по строкам листа «Сплит доходов» — формулами; данные мастер-файлов и модели бюджета 2027 (AdTech_2027_1021_cons) — значениями на 23.10.2026.
B4: 1. Сбор выручки: компоненты и представления
B5: Компонент | C5: Строки «Сплита доходов» | D5: 9 мес. 2026 | E5: Корпоративный P&L AdTech (портал корпоративной отчётности) | F5: Мастер-файл: BiP (Rev) — сегменты, инкремент, свод для консолидации, E-com, КПЭ, сегментный P&L для финансов OMNI | G5: Мастер-файл: управленческий P&L (MBR, trading deck, прогноз) | H5: Mads Commercial (Д. Ардаширов) | I5: КПЭ сотрудников, ежеквартально (КПЭ 125, лист «Подтверждение КПЭ»)
B6: Направления AdTech: БиП на РН AdTech без поставщиков М+ | C6: 6 (стр. 7–17) | D6: ='Сплит доходов'!L6 -> 5359.1209 | E6: ✓ | F6: ✓ | G6: ✓* | H6: ✓* | I6: ✓*
B7: в т.ч. E-com (E-Commerce_Adtech, включая РА и «условное») | C7: 14–17 | D7: =SUM('Сплит доходов'!L14:L17) -> 3204.8024 | E7: ✓ | F7: ✓ сегменты E-com, выгрузка «E-Com FC» | G7: ✓* строка APP | H7: ✓* | I7: ✓*
B8: в т.ч. не E-com (Реклама и продвижение, Прочее, Лояльность М+ на РН AdTech) | C8: 7–13 | D8: ='Сплит доходов'!L6-SUM('Сплит доходов'!L14:L17) -> 2154.3184 | E8: ✓ | F8: ✓ инкремент без E-comm → свод для консолидации | G8: ✓* | H8: ✓* | I8: ✓*
B9: Поставщики М+: БиП на РН AdTech (с апреля) | C9: 18 (стр. 19–27) | D9: ='Сплит доходов'!L18 -> 995.65418 | E9: ✓ | F9: ✓ | G9: — | H9: — | I9: ✓*
B10: 1С: услуги лояльности (банки, партнёры), реклама непоставщикам, размещение на сайте | C10: 28 | D10: ='Сплит доходов'!L28 -> 274.03774 | E10: ✓ | F10: — | G10: ✓* кроме М+ | H10: ✓* | I10: ✓*
B11: Доходы на РН других направлений: сделки по данным ДО AdTech | C11: 33 (стр. 34–43) | D11: ='Сплит доходов'!L33 -> 1267.7307 | E11: — | F11: — | G11: ✓* кроме М+ | H11: ✓* | I11: —
B12: в т.ч. М+ | C12: 36 | D12: ='Сплит доходов'!L36 -> 333.08446 | E12: — | F12: — | G12: — | H12: — | I12: —
B13: Итого в представлении, 9 мес. 2026 | D13: ='Сплит доходов'!L5+'Сплит доходов'!L33 -> 7896.5435 | E13: ='Сплит доходов'!L5 -> 6628.8128 | F13: 6357.887 | G13: 6718.37 | H13: 6783.93 | I13: 3142.727
B14: Как собирается итог | E14: «Сплит доходов», стр. 5: БиП на РН AdTech + 1С (лист «PL AdTech») | F14: Выгрузка «Бонусы и скидки» + «Бонусы» по РН AdTech (мастер-файл, лист «Rev вход»); совпадает со «Сплитом» (стр. 6 + 18) с точностью до 3,1 (июль) | G14: «Данные УО AdTech» (в мастер-файле — «Расшифровка») по инвентарю, без инвентаря М+: свод УО 8 129,2 − М+ 1 410,9 | H14: Свод УО по направлениям, поставщики / не поставщики (лист «Mads Commercial» файла доходов). Выше управленческого P&L на 65,5: включает М+ через 1С (64,2) | I14: УО за квартал без доходов на РН других направлений, включая М+. Показатель за Q3: поставщики 2 782,5 + не поставщики 360,3
B15: ✓* — представление формируется не из строк «Сплита доходов», а из «Данных УО AdTech» по инвентарю. Свод УО (8 129,2) больше суммы компонентов «Сплита» (7 896,5) на 232,7: доходы по РН AdTech +271,2 (в УО 6 626,0, в БиП 6 354,8; из них 186,4 приходится на июль — КУ, отражённые в БиП в прошлых месяцах, учтены в УО в июле повторно на инвентаре М+ (75,4) и Digital Instore (64,4)), доходы на РН других направлений +25,4, корректировки прошлых месяцев +18,3, 1С −82,3 (в УО 191,7, в «Сплите» 274,0). Лист «Сверка» файла доходов показывает по РН AdTech 283,5: суммы БиП там внесены вручную с округлением до млн руб.
B17: Перераспределение бюджетов поставщиков в инструменты AdTech: эффект для компании
B18: 1. Источник роста. Часть роста выручки AdTech обеспечивают бюджеты поставщиков, которые переходят из классических коммерческих условий (премии, промо, разовые условия) в рекламные инструменты. Для компании это смена формы, в которой поставщик инвестирует в продажи, а не перераспределение выручки между направлениями.
B19: 2. РТО. Размещения в приложении, в магазинах (Digital Instore) и в онлайне продвигают товары поставщика в каналах Магнита и стимулируют их продажи, то есть дают вклад в товарооборот, а не только компенсируют коммерческие условия.
B20: 3. Маржинальность. В отличие от промо-компенсаций, которые покрывают снижение цены, рекламный доход не требует скидки на полке. Расходы, привязанные к выручке AdTech (закупка трафика, вознаграждения РА, креаторы), в бюджете 2027 г. составляют 13,5% выручки; рентабельность AdTech по EBITDA — 74%.
B21: 4. Динамика. По анализу Magnit Ads за 9 мес. 2026 г. сегменты маркетинговых доходов, в которых учитывается выручка AdTech, растут быстрее остальных: «Маркетинг» +86%, прочие бонусы от поставщиков +19%; в сегментах без AdTech премии +3%, промо на уровне прошлого года, разовые условия −7%. Сегмент «Маркетинг» дал 85% прироста маркетинговых доходов: поставщики переводят бюджеты в инструменты с измеримым эффектом.
B23: 2. Регулярные выгрузки и отчёты с выручкой
B24: Выгрузка / отчёт | C24: Кому | D24: Как часто | E24: Где формируется | F24: Какая выручка | G24: 9 мес. 2026 | H24: 2026: факт + прогноз | I24: Комментарий
B25: Корпоративный P&L AdTech | C25: Корпоративная отчётность (портал «Отчёт PL AdTech») | D25: ежемесячно | E25: Лист «PL AdTech» = «Сплит доходов», стр. 5 | F25: БиП на РН AdTech (включая поставщиков М+) + 1С | G25: ='Сплит доходов'!L5 -> 6628.8128 | H25: — | I25: Доходы на РН других направлений не входят
B26: Управленческий P&L AdTech: MBR, «OMNI KPI Summary. AdTech» (trading deck), отчёт BU vs факт | C26: Руководство | D26: ежемесячно; trading deck — еженедельно | E26: Мастер-файл: '10 PL' → '13 Для слайда', '19 Trading deck weekly', '11 Reports' | F26: Вся выручка свода УО по инвентарю, без М+ | G26: 6718.37 | H26: 10606.11 | I26: Факт — «Данные УО AdTech» и «Общий свод УО». Инвентарь сопоставляется со строками P&L; ФинТех, TV, Гетблоггер, реклама на транспорте и прочее относятся в Other; М+ исключается. Помесячно архивные данные могут отличаться от УО, итог 9 мес. совпадает
B27: Свод для консолидации «Adtech_прогноз 9+3 для конс» | C27: Консолидация, контроллинг | D27: ежемесячно | E27: Мастер-файл: '15 CONS' A93:M152 → лист «Свод» | F27: Инкремент выручки без E-comm по BiP без ADJ ('12 Сегменты', стр. 13 + 15); Commercial margin — за вычетом вознаграждений РА и блогерам | G27: 2375.81 | H27: 3439.42 | I27: Отправленные месяцы фиксируются в архиве и не пересчитываются. Commercial margin 2026 г. — 3 171,3
B28: E-Com «E-Com_FC_9+3» | C28: FT | D28: ежемесячно | E28: Мастер-файл: '32 E-comm' B61:O66 | F28: Выручка APP из P&L: поставщики / не поставщики + признание выручки с РН других направлений (ручная корректировка) | G28: 3362.05 | H28: 6090.26 | I28: Дополнительно учтено 200 — признание выручки с РН других направлений (ноябрь и декабрь по 100). Корректировка есть только в этой выгрузке, в P&L и MBR не входит
B29: КПЭ AdTech | C29: Расчёт триггеров КПЭ | D29: ежемесячно | E29: Мастер-файл: '14 Триггеры' | F29: Rev / BiP без ADJ за вычетом фиксированной базы E-com поставщиков (3 930 в год); Non-vendor — не поставщики / инкремент | G29: 3418.48 | H29: 6247.09 | I29: Применяется сценарий 1. Сценарий 2 (с «Другое» и «ФинТех» из «Расшифровки») не используется
B30: КПЭ сотрудников | C30: HR, C&B | D30: ежеквартально | E30: Файл доходов, лист «Подтверждение КПЭ» | F30: УО по РН AdTech + 1С + корректировки, включая М+, без доходов на РН других направлений | G30: 3142.727 | H30: — | I30: Показатель за Q3, а не за 9 мес.: поставщики 2 782,5, не поставщики 360,3
B31: Mads Commercial | C31: Коммерция (Google-таблица Mads Commercial) | D31: оперативно | E31: Файл доходов, лист «Mads Commercial» | F31: Свод УО по направлениям: поставщики / не поставщики | G31: 6783.93 | H31: — | I31: Выше управленческого P&L на 65,5: включает М+ через 1С
B32: Сегменты и инкремент | C32: Сегментная выручка для OMNI (Загудалова); база для свода консолидации, КПЭ и E-Com | D32: ежемесячно | E32: Мастер-файл: '31 Инкремент' → '12 Сегменты' | F32: BiP по контрагентам (= «Сплит доходов», стр. 6 + 18) | G32: 6357.887 | H32: 10177.13 | I32: Отличие от управленческого P&L (ADJ): 9 мес. — 360,5, год — 429,0
B33: Доходы М+ | C33: Уточняется | D33: — | E33: Файл доходов, лист «М+» | F33: Доходы М+ по РН AdTech + ручные добавления (не все доходы М+ маркируются AdTech); учёт с марта 2026 г. | G33: — | H33: —
B34: Доходы E-com | C34: Уточняется | D34: — | E34: Файл доходов, лист «Ecom» | F34: Доходы с признаком Ecom: поставщики / не поставщики, инвентарь, топ-10 контрагентов | G34: — | H34: —
B35: FC 2026 в модели бюджета 2027 | C35: — | D35: разово | E35: Модель «AdTech_2027_1021_cons», столбец 2026 | F35: См. раздел 3 | G35: — | H35: 10323.41 | I35: Выручка — мастер-файл по итогам июля (факт янв–июл + прогноз сен–дек) и август, разнесённый вручную. Расходы и CAPEX — в основном BU 2026 после ревизии
B37: 3. Как собран FC 2026 для бюджета 2027
B38: Направление | C38: FC 2026 в модели | D38: Мастер-файл по итогам июля | E38: Модель − мастер-файл | F38: Как собрано / что в разнице
B39: APP | C39: 6195.4 | D39: 5701.07 | E39: =C39-D39 -> 494.33 | F39: Январь–июль и сентябрь–декабрь — из мастер-файла. Разница — август (494,3): в мастер-файле за август указан только общий итог без разбивки по направлениям. В модели APP введён одним значением (лист «APP Перформанс», O28)
B40: Instore digital (включая 2.0) | C40: 2446.09 | D40: 2206.84 | E40: =C40-D40 -> 239.25 | F40: Сентябрь–декабрь совпадают помесячно с суммой Instore digital и digital 2.0: 297,1 / 213,7 / 285,9 / 406,8. Разница — август 239,4 (≈ 0,81 × сентябрь)
B41: DMP+Online | C41: 987 | D41: 889.81 | E41: =C41-D41 -> 97.19 | F41: Сентябрь–декабрь совпадают: 120,8 / 86,9 / 116,3 / 165,4. Разница — август 97,3 (≈ 0,81 × сентябрь)
B42: DMP+Analytics | C42: 102.4 | D42: 90.76 | E42: =C42-D42 -> 11.64 | F42: Сентябрь–декабрь совпадают: 14,2 / 10,2 / 13,7 / 19,5. Разница — август 11,5
B43: RMN (бренд-бюджеты) / прочие направления мастер-файла | C43: 592.6 | D43: 619.51 | E43: =C43-D43 -> -26.91 | F43: Отдельной строки RMN в мастер-файле нет. По величине 592,6 соответствует прочим направлениям мастер-файла: POSM 98,0 + Other 286,9 + пакеты 214,8 + Magnit Market 13,4 + MIP 6,5. С учётом этой строки итог модели совпадает с мастер-файлом с точностью до 2,5. Источник разницы 26,9 не установлен
B44: Август итогом | C44: 0 | D44: 817.9 | E44: =C44-D44 -> -817.9 | F44: Предварительный август внесён в мастер-файл одной суммой; в модели он разнесён по направлениям (см. разницы в строках выше)
...
